2018-11-29 22:18:45,955 - util.py[DEBUG]: Cloud-init v. 18.3-9-g2e62cb8a-0ubuntu1~16.04.2 running 'init-local' at Thu, 29 Nov 2018 22:18:45 +0000. Up 8.41 seconds.
2018-11-29 22:18:45,955 - main.py[DEBUG]: No kernel command line url found.
2018-11-29 22:18:45,955 - main.py[DEBUG]: Closing stdin.
2018-11-29 22:18:45,958 - util.py[DEBUG]: Writing to /var/log/cloud-init.log - ab: [644] 0 bytes
2018-11-29 22:18:45,959 - util.py[DEBUG]: Changing the ownership of /var/log/cloud-init.log to 104:4
2018-11-29 22:18:45,959 - util.py[DEBUG]: Attempting to remove /var/lib/cloud/instance/boot-finished
2018-11-29 22:18:45,959 - util.py[DEBUG]: Attempting to remove /var/lib/cloud/data/no-net
2018-11-29 22:18:45,960 - handlers.py[DEBUG]: start: init-local/check-cache: attempting to read from cache [check]
2018-11-29 22:18:45,960 - util.py[DEBUG]: Reading from /var/lib/cloud/instance/obj.pkl (quiet=False)
2018-11-29 22:18:45,960 - stages.py[DEBUG]: no cache found
2018-11-29 22:18:45,960 - handlers.py[DEBUG]: finish: init-local/check-cache: SUCCESS: no cache found
2018-11-29 22:18:45,960 - util.py[DEBUG]: Attempting to remove /var/lib/cloud/instance
2018-11-29 22:18:45,969 - stages.py[DEBUG]: Using distro class <class 'cloudinit.distros.ubuntu.Distro'>
2018-11-29 22:18:45,969 - __init__.py[DEBUG]: Looking for data source in: ['NoCloud', 'ConfigDrive', 'OpenNebula', 'DigitalOcean', 'Azure', 'AltCloud', 'OVF', 'MAAS', 'GCE', 'OpenStack', 'CloudSigma', 'SmartOS', 'Bigstep', 'Scaleway', 'AliYun', 'Ec2', 'CloudStack', 'None'], via packages ['', 'cloudinit.sources'] that matches dependencies ['FILESYSTEM']
2018-11-29 22:18:46,007 - util.py[DEBUG]: Reading from /etc/os-release (quiet=False)
2018-11-29 22:18:46,008 - util.py[DEBUG]: Read 298 bytes from /etc/os-release
2018-11-29 22:18:46,043 - __init__.py[DEBUG]: Searching for local data source in: ['DataSourceNoCloud', 'DataSourceConfigDrive', 'DataSourceOpenNebula', 'DataSourceDigitalOcean', 'DataSourceAzure', 'DataSourceOVF', 'DataSourceOpenStackLocal', 'DataSourceCloudSigma', 'DataSourceSmartOS', 'DataSourceEc2Local']
2018-11-29 22:18:46,043 - handlers.py[DEBUG]: start: init-local/search-NoCloud: searching for local data from DataSourceNoCloud
2018-11-29 22:18:46,043 - __init__.py[DEBUG]: Seeing if we can get any data from <class 'cloudinit.sources.DataSourceNoCloud.DataSourceNoCloud'>
2018-11-29 22:18:46,043 - __init__.py[DEBUG]: Update datasource metadata and network config due to events: New instance first boot
2018-11-29 22:18:46,043 - util.py[DEBUG]: Running command ['systemd-detect-virt', '--quiet', '--container'] with allowed return codes [0] (shell=False, capture=True)
2018-11-29 22:18:46,045 - util.py[DEBUG]: Running command ['running-in-container'] with allowed return codes [0] (shell=False, capture=True)
2018-11-29 22:18:46,046 - util.py[DEBUG]: Running command ['lxc-is-container'] with allowed return codes [0] (shell=False, capture=True)
2018-11-29 22:18:46,048 - util.py[DEBUG]: Reading from /proc/1/environ (quiet=False)
2018-11-29 22:18:46,048 - util.py[DEBUG]: Read 150 bytes from /proc/1/environ
2018-11-29 22:18:46,048 - util.py[DEBUG]: Reading from /proc/self/status (quiet=False)
2018-11-29 22:18:46,048 - util.py[DEBUG]: Read 966 bytes from /proc/self/status
2018-11-29 22:18:46,048 - util.py[DEBUG]: querying dmi data /sys/class/dmi/id/product_serial
2018-11-29 22:18:46,049 - util.py[DEBUG]: Reading from /sys/class/dmi/id/product_serial (quiet=False)
2018-11-29 22:18:46,049 - util.py[DEBUG]: Read 37 bytes from /sys/class/dmi/id/product_serial
2018-11-29 22:18:46,049 - util.py[DEBUG]: dmi data /sys/class/dmi/id/product_serial returned ec2858ca-12b8-2dcb-fc7e-893f50609c10
2018-11-29 22:18:46,049 - util.py[DEBUG]: Reading from /var/lib/cloud/seed/nocloud/user-data (quiet=False)
2018-11-29 22:18:46,049 - util.py[DEBUG]: Reading from /var/lib/cloud/seed/nocloud/meta-data (quiet=False)
2018-11-29 22:18:46,049 - util.py[DEBUG]: Reading from /var/lib/cloud/seed/nocloud/vendor-data (quiet=False)
2018-11-29 22:18:46,049 - util.py[DEBUG]: Reading from /var/lib/cloud/seed/nocloud/network-config (quiet=False)
2018-11-29 22:18:46,049 - util.py[DEBUG]: Reading from /var/lib/cloud/seed/nocloud-net/user-data (quiet=False)
2018-11-29 22:18:46,049 - util.py[DEBUG]: Reading from /var/lib/cloud/seed/nocloud-net/meta-data (quiet=False)
2018-11-29 22:18:46,049 - util.py[DEBUG]: Reading from /var/lib/cloud/seed/nocloud-net/vendor-data (quiet=False)
2018-11-29 22:18:46,049 - util.py[DEBUG]: Reading from /var/lib/cloud/seed/nocloud-net/network-config (quiet=False)
2018-11-29 22:18:46,049 - util.py[DEBUG]: Running command ['blkid', '-odevice', '/dev/sr0'] with allowed return codes [0, 2] (shell=False, capture=True)
2018-11-29 22:18:46,051 - util.py[DEBUG]: Running command ['blkid', '-odevice', '/dev/sr1'] with allowed return codes [0, 2] (shell=False, capture=True)
2018-11-29 22:18:46,053 - util.py[DEBUG]: Running command ['blkid', '-tTYPE=vfat', '-odevice'] with allowed return codes [0, 2] (shell=False, capture=True)
2018-11-29 22:18:46,066 - util.py[DEBUG]: Running command ['blkid', '-tTYPE=iso9660', '-odevice'] with allowed return codes [0, 2] (shell=False, capture=True)
2018-11-29 22:18:46,079 - util.py[DEBUG]: Running command ['blkid', '-tLABEL=cidata', '-odevice'] with allowed return codes [0, 2] (shell=False, capture=True)
2018-11-29 22:18:46,091 - handlers.py[DEBUG]: finish: init-local/search-NoCloud: SUCCESS: no local data found from DataSourceNoCloud
2018-11-29 22:18:46,091 - handlers.py[DEBUG]: start: init-local/search-ConfigDrive: searching for local data from DataSourceConfigDrive
2018-11-29 22:18:46,091 - __init__.py[DEBUG]: Seeing if we can get any data from <class 'cloudinit.sources.DataSourceConfigDrive.DataSourceConfigDrive'>
2018-11-29 22:18:46,091 - __init__.py[DEBUG]: Update datasource metadata and network config due to events: New instance first boot
2018-11-29 22:18:46,092 - util.py[DEBUG]: Running command ['blkid', '-odevice', '/dev/sr0'] with allowed return codes [0, 2] (shell=False, capture=True)
2018-11-29 22:18:46,093 - util.py[DEBUG]: Running command ['blkid', '-odevice', '/dev/sr1'] with allowed return codes [0, 2] (shell=False, capture=True)
2018-11-29 22:18:46,094 - util.py[DEBUG]: Running command ['blkid', '-odevice', '/dev/cd0'] with allowed return codes [0, 2] (shell=False, capture=True)
2018-11-29 22:18:46,096 - util.py[DEBUG]: Running command ['blkid', '-odevice', '/dev/cd1'] with allowed return codes [0, 2] (shell=False, capture=True)
2018-11-29 22:18:46,098 - util.py[DEBUG]: Running command ['blkid', '-tTYPE=vfat', '-odevice'] with allowed return codes [0, 2] (shell=False, capture=True)
2018-11-29 22:18:46,110 - util.py[DEBUG]: Running command ['blkid', '-tTYPE=iso9660', '-odevice'] with allowed return codes [0, 2] (shell=False, capture=True)
2018-11-29 22:18:46,122 - util.py[DEBUG]: Running command ['blkid', '-tLABEL=config-2', '-odevice'] with allowed return codes [0, 2] (shell=False, capture=True)
2018-11-29 22:18:46,134 - util.py[DEBUG]: Running command ['blkid', '-tLABEL=CONFIG-2', '-odevice'] with allowed return codes [0, 2] (shell=False, capture=True)
2018-11-29 22:18:46,146 - DataSourceConfigDrive.py[DEBUG]: devices=[] dslist=['NoCloud', 'ConfigDrive', 'OpenNebula', 'DigitalOcean', 'Azure', 'AltCloud', 'OVF', 'MAAS', 'GCE', 'OpenStack', 'CloudSigma', 'SmartOS', 'Bigstep', 'Scaleway', 'AliYun', 'Ec2', 'CloudStack', 'None']
2018-11-29 22:18:46,146 - handlers.py[DEBUG]: finish: init-local/search-ConfigDrive: SUCCESS: no local data found from DataSourceConfigDrive
2018-11-29 22:18:46,146 - handlers.py[DEBUG]: start: init-local/search-OpenNebula: searching for local data from DataSourceOpenNebula
2018-11-29 22:18:46,146 - __init__.py[DEBUG]: Seeing if we can get any data from <class 'cloudinit.sources.DataSourceOpenNebula.DataSourceOpenNebula'>
2018-11-29 22:18:46,146 - __init__.py[DEBUG]: Update datasource metadata and network config due to events: New instance first boot
2018-11-29 22:18:46,146 - util.py[DEBUG]: Running command ['blkid', '-tLABEL=CONTEXT', '-odevice'] with allowed return codes [0, 2] (shell=False, capture=True)
2018-11-29 22:18:46,158 - util.py[DEBUG]: Running command ['blkid', '-tLABEL=CDROM', '-odevice'] with allowed return codes [0, 2] (shell=False, capture=True)
2018-11-29 22:18:46,170 - util.py[DEBUG]: Running command ['blkid', '-tTYPE=iso9660', '-odevice'] with allowed return codes [0, 2] (shell=False, capture=True)
2018-11-29 22:18:46,182 - handlers.py[DEBUG]: finish: init-local/search-OpenNebula: SUCCESS: no local data found from DataSourceOpenNebula
2018-11-29 22:18:46,182 - handlers.py[DEBUG]: start: init-local/search-DigitalOcean: searching for local data from DataSourceDigitalOcean
2018-11-29 22:18:46,182 - __init__.py[DEBUG]: Seeing if we can get any data from <class 'cloudinit.sources.DataSourceDigitalOcean.DataSourceDigitalOcean'>
2018-11-29 22:18:46,183 - __init__.py[DEBUG]: Update datasource metadata and network config due to events: New instance first boot
2018-11-29 22:18:46,183 - util.py[DEBUG]: Running command ['systemd-detect-virt', '--quiet', '--container'] with allowed return codes [0] (shell=False, capture=True)
2018-11-29 22:18:46,184 - util.py[DEBUG]: Running command ['running-in-container'] with allowed return codes [0] (shell=False, capture=True)
2018-11-29 22:18:46,186 - util.py[DEBUG]: Running command ['lxc-is-container'] with allowed return codes [0] (shell=False, capture=True)
2018-11-29 22:18:46,188 - util.py[DEBUG]: Reading from /proc/1/environ (quiet=False)
2018-11-29 22:18:46,188 - util.py[DEBUG]: Read 150 bytes from /proc/1/environ
2018-11-29 22:18:46,188 - util.py[DEBUG]: Reading from /proc/self/status (quiet=False)
2018-11-29 22:18:46,188 - util.py[DEBUG]: Read 966 bytes from /proc/self/status
2018-11-29 22:18:46,188 - util.py[DEBUG]: querying dmi data /sys/class/dmi/id/sys_vendor
2018-11-29 22:18:46,188 - util.py[DEBUG]: Reading from /sys/class/dmi/id/sys_vendor (quiet=False)
2018-11-29 22:18:46,188 - util.py[DEBUG]: Read 4 bytes from /sys/class/dmi/id/sys_vendor
2018-11-29 22:18:46,189 - util.py[DEBUG]: dmi data /sys/class/dmi/id/sys_vendor returned Xen
2018-11-29 22:18:46,189 - handlers.py[DEBUG]: finish: init-local/search-DigitalOcean: SUCCESS: no local data found from DataSourceDigitalOcean
2018-11-29 22:18:46,189 - handlers.py[DEBUG]: start: init-local/search-Azure: searching for local data from DataSourceAzure
2018-11-29 22:18:46,189 - __init__.py[DEBUG]: Seeing if we can get any data from <class 'cloudinit.sources.DataSourceAzure.DataSourceAzure'>
2018-11-29 22:18:46,189 - __init__.py[DEBUG]: Update datasource metadata and network config due to events: New instance first boot
2018-11-29 22:18:46,189 - util.py[DEBUG]: Running command ['systemd-detect-virt', '--quiet', '--container'] with allowed return codes [0] (shell=False, capture=True)
2018-11-29 22:18:46,191 - util.py[DEBUG]: Running command ['running-in-container'] with allowed return codes [0] (shell=False, capture=True)
2018-11-29 22:18:46,192 - util.py[DEBUG]: Running command ['lxc-is-container'] with allowed return codes [0] (shell=False, capture=True)
2018-11-29 22:18:46,194 - util.py[DEBUG]: Reading from /proc/1/environ (quiet=False)
2018-11-29 22:18:46,194 - util.py[DEBUG]: Read 150 bytes from /proc/1/environ
2018-11-29 22:18:46,194 - util.py[DEBUG]: Reading from /proc/self/status (quiet=False)
2018-11-29 22:18:46,194 - util.py[DEBUG]: Read 966 bytes from /proc/self/status
2018-11-29 22:18:46,194 - util.py[DEBUG]: querying dmi data /sys/class/dmi/id/chassis_asset_tag
2018-11-29 22:18:46,194 - util.py[DEBUG]: Reading from /sys/class/dmi/id/chassis_asset_tag (quiet=False)
2018-11-29 22:18:46,194 - util.py[DEBUG]: Read 1 bytes from /sys/class/dmi/id/chassis_asset_tag
2018-11-29 22:18:46,194 - util.py[DEBUG]: dmi data /sys/class/dmi/id/chassis_asset_tag returned 
2018-11-29 22:18:46,194 - DataSourceAzure.py[DEBUG]: Non-Azure DMI asset tag '' discovered.
2018-11-29 22:18:46,194 - handlers.py[DEBUG]: finish: init-local/search-Azure: SUCCESS: no local data found from DataSourceAzure
2018-11-29 22:18:46,195 - handlers.py[DEBUG]: start: init-local/search-OVF: searching for local data from DataSourceOVF
2018-11-29 22:18:46,195 - __init__.py[DEBUG]: Seeing if we can get any data from <class 'cloudinit.sources.DataSourceOVF.DataSourceOVF'>
2018-11-29 22:18:46,195 - __init__.py[DEBUG]: Update datasource metadata and network config due to events: New instance first boot
2018-11-29 22:18:46,195 - util.py[DEBUG]: Running command ['systemd-detect-virt', '--quiet', '--container'] with allowed return codes [0] (shell=False, capture=True)
2018-11-29 22:18:46,196 - util.py[DEBUG]: Running command ['running-in-container'] with allowed return codes [0] (shell=False, capture=True)
2018-11-29 22:18:46,198 - util.py[DEBUG]: Running command ['lxc-is-container'] with allowed return codes [0] (shell=False, capture=True)
2018-11-29 22:18:46,200 - util.py[DEBUG]: Reading from /proc/1/environ (quiet=False)
2018-11-29 22:18:46,200 - util.py[DEBUG]: Read 150 bytes from /proc/1/environ
2018-11-29 22:18:46,200 - util.py[DEBUG]: Reading from /proc/self/status (quiet=False)
2018-11-29 22:18:46,200 - util.py[DEBUG]: Read 966 bytes from /proc/self/status
2018-11-29 22:18:46,200 - util.py[DEBUG]: querying dmi data /sys/class/dmi/id/product_name
2018-11-29 22:18:46,200 - util.py[DEBUG]: Reading from /sys/class/dmi/id/product_name (quiet=False)
2018-11-29 22:18:46,200 - util.py[DEBUG]: Read 9 bytes from /sys/class/dmi/id/product_name
2018-11-29 22:18:46,200 - util.py[DEBUG]: dmi data /sys/class/dmi/id/product_name returned HVM domU
2018-11-29 22:18:46,200 - util.py[DEBUG]: Reading from /proc/mounts (quiet=False)
2018-11-29 22:18:46,201 - util.py[DEBUG]: Read 1991 bytes from /proc/mounts
2018-11-29 22:18:46,201 - util.py[DEBUG]: Fetched {'pstore': {'mountpoint': '/sys/fs/pstore', 'opts': 'rw,nosuid,nodev,noexec,relatime', 'fstype': 'pstore'}, 'udev': {'mountpoint': '/dev', 'opts': 'rw,nosuid,relatime,size=30907648k,nr_inodes=7726912,mode=755', 'fstype': 'devtmpfs'}, 'securityfs': {'mountpoint': '/sys/kernel/security', 'opts': 'rw,nosuid,nodev,noexec,relatime', 'fstype': 'securityfs'}, 'cgroup': {'mountpoint': '/sys/fs/cgroup/cpuset', 'opts': 'rw,nosuid,nodev,noexec,relatime,cpuset', 'fstype': 'cgroup'}, 'fusectl': {'mountpoint': '/sys/fs/fuse/connections', 'opts': 'rw,relatime', 'fstype': 'fusectl'}, 'hugetlbfs': {'mountpoint': '/dev/hugepages', 'opts': 'rw,relatime', 'fstype': 'hugetlbfs'}, '/dev/xvda1': {'mountpoint': '/', 'opts': 'rw,relatime,discard,data=ordered', 'fstype': 'ext4'}, 'devpts': {'mountpoint': '/dev/pts', 'opts': 'rw,nosuid,noexec,relatime,gid=5,mode=620,ptmxmode=000', 'fstype': 'devpts'}, 'debugfs': {'mountpoint': '/sys/kernel/debug', 'opts': 'rw,relatime', 'fstype': 'debugfs'}, 'mqueue': {'mountpoint': '/dev/mqueue', 'opts': 'rw,relatime', 'fstype': 'mqueue'}, 'sysfs': {'mountpoint': '/sys', 'opts': 'rw,nosuid,nodev,noexec,relatime', 'fstype': 'sysfs'}, 'systemd-1': {'mountpoint': '/proc/sys/fs/binfmt_misc', 'opts': 'rw,relatime,fd=33,pgrp=1,timeout=0,minproto=5,maxproto=5,direct', 'fstype': 'autofs'}, 'tmpfs': {'mountpoint': '/sys/fs/cgroup', 'opts': 'ro,nosuid,nodev,noexec,mode=755', 'fstype': 'tmpfs'}, 'proc': {'mountpoint': '/proc', 'opts': 'rw,nosuid,nodev,noexec,relatime', 'fstype': 'proc'}} mounts from proc
2018-11-29 22:18:46,201 - util.py[DEBUG]: Running command ['blkid', '-tTYPE=iso9660', '-odevice'] with allowed return codes [0, 2] (shell=False, capture=True)
2018-11-29 22:18:46,213 - handlers.py[DEBUG]: finish: init-local/search-OVF: SUCCESS: no local data found from DataSourceOVF
2018-11-29 22:18:46,213 - handlers.py[DEBUG]: start: init-local/search-OpenStackLocal: searching for local data from DataSourceOpenStackLocal
2018-11-29 22:18:46,213 - __init__.py[DEBUG]: Seeing if we can get any data from <class 'cloudinit.sources.DataSourceOpenStack.DataSourceOpenStackLocal'>
2018-11-29 22:18:46,213 - __init__.py[DEBUG]: Update datasource metadata and network config due to events: New instance first boot
2018-11-29 22:18:46,213 - util.py[DEBUG]: Running command ['systemd-detect-virt', '--quiet', '--container'] with allowed return codes [0] (shell=False, capture=True)
2018-11-29 22:18:46,215 - util.py[DEBUG]: Running command ['running-in-container'] with allowed return codes [0] (shell=False, capture=True)
2018-11-29 22:18:46,216 - util.py[DEBUG]: Running command ['lxc-is-container'] with allowed return codes [0] (shell=False, capture=True)
2018-11-29 22:18:46,218 - util.py[DEBUG]: Reading from /proc/1/environ (quiet=False)
2018-11-29 22:18:46,218 - util.py[DEBUG]: Read 150 bytes from /proc/1/environ
2018-11-29 22:18:46,218 - util.py[DEBUG]: Reading from /proc/self/status (quiet=False)
2018-11-29 22:18:46,218 - util.py[DEBUG]: Read 966 bytes from /proc/self/status
2018-11-29 22:18:46,218 - util.py[DEBUG]: querying dmi data /sys/class/dmi/id/product_name
2018-11-29 22:18:46,218 - util.py[DEBUG]: Reading from /sys/class/dmi/id/product_name (quiet=False)
2018-11-29 22:18:46,218 - util.py[DEBUG]: Read 9 bytes from /sys/class/dmi/id/product_name
2018-11-29 22:18:46,219 - util.py[DEBUG]: dmi data /sys/class/dmi/id/product_name returned HVM domU
2018-11-29 22:18:46,219 - util.py[DEBUG]: Running command ['systemd-detect-virt', '--quiet', '--container'] with allowed return codes [0] (shell=False, capture=True)
2018-11-29 22:18:46,220 - util.py[DEBUG]: Running command ['running-in-container'] with allowed return codes [0] (shell=False, capture=True)
2018-11-29 22:18:46,222 - util.py[DEBUG]: Running command ['lxc-is-container'] with allowed return codes [0] (shell=False, capture=True)
2018-11-29 22:18:46,223 - util.py[DEBUG]: Reading from /proc/1/environ (quiet=False)
2018-11-29 22:18:46,224 - util.py[DEBUG]: Read 150 bytes from /proc/1/environ
2018-11-29 22:18:46,224 - util.py[DEBUG]: Reading from /proc/self/status (quiet=False)
2018-11-29 22:18:46,224 - util.py[DEBUG]: Read 966 bytes from /proc/self/status
2018-11-29 22:18:46,224 - util.py[DEBUG]: querying dmi data /sys/class/dmi/id/chassis_asset_tag
2018-11-29 22:18:46,224 - util.py[DEBUG]: Reading from /sys/class/dmi/id/chassis_asset_tag (quiet=False)
2018-11-29 22:18:46,224 - util.py[DEBUG]: Read 1 bytes from /sys/class/dmi/id/chassis_asset_tag
2018-11-29 22:18:46,224 - util.py[DEBUG]: dmi data /sys/class/dmi/id/chassis_asset_tag returned 
2018-11-29 22:18:46,224 - util.py[DEBUG]: Reading from /proc/1/environ (quiet=False)
2018-11-29 22:18:46,224 - util.py[DEBUG]: Read 150 bytes from /proc/1/environ
2018-11-29 22:18:46,224 - handlers.py[DEBUG]: finish: init-local/search-OpenStackLocal: SUCCESS: no local data found from DataSourceOpenStackLocal
2018-11-29 22:18:46,224 - handlers.py[DEBUG]: start: init-local/search-CloudSigma: searching for local data from DataSourceCloudSigma
2018-11-29 22:18:46,224 - __init__.py[DEBUG]: Seeing if we can get any data from <class 'cloudinit.sources.DataSourceCloudSigma.DataSourceCloudSigma'>
2018-11-29 22:18:46,225 - __init__.py[DEBUG]: Update datasource metadata and network config due to events: New instance first boot
2018-11-29 22:18:46,225 - DataSourceCloudSigma.py[DEBUG]: determining hypervisor product name via dmi data
2018-11-29 22:18:46,225 - util.py[DEBUG]: Running command ['systemd-detect-virt', '--quiet', '--container'] with allowed return codes [0] (shell=False, capture=True)
2018-11-29 22:18:46,226 - util.py[DEBUG]: Running command ['running-in-container'] with allowed return codes [0] (shell=False, capture=True)
2018-11-29 22:18:46,227 - util.py[DEBUG]: Running command ['lxc-is-container'] with allowed return codes [0] (shell=False, capture=True)
2018-11-29 22:18:46,229 - util.py[DEBUG]: Reading from /proc/1/environ (quiet=False)
2018-11-29 22:18:46,229 - util.py[DEBUG]: Read 150 bytes from /proc/1/environ
2018-11-29 22:18:46,229 - util.py[DEBUG]: Reading from /proc/self/status (quiet=False)
2018-11-29 22:18:46,229 - util.py[DEBUG]: Read 966 bytes from /proc/self/status
2018-11-29 22:18:46,229 - util.py[DEBUG]: querying dmi data /sys/class/dmi/id/product_name
2018-11-29 22:18:46,229 - util.py[DEBUG]: Reading from /sys/class/dmi/id/product_name (quiet=False)
2018-11-29 22:18:46,229 - util.py[DEBUG]: Read 9 bytes from /sys/class/dmi/id/product_name
2018-11-29 22:18:46,229 - util.py[DEBUG]: dmi data /sys/class/dmi/id/product_name returned HVM domU
2018-11-29 22:18:46,229 - DataSourceCloudSigma.py[DEBUG]: detected hypervisor as HVM domU
2018-11-29 22:18:46,229 - handlers.py[DEBUG]: finish: init-local/search-CloudSigma: SUCCESS: no local data found from DataSourceCloudSigma
2018-11-29 22:18:46,229 - handlers.py[DEBUG]: start: init-local/search-SmartOS: searching for local data from DataSourceSmartOS
2018-11-29 22:18:46,230 - __init__.py[DEBUG]: Seeing if we can get any data from <class 'cloudinit.sources.DataSourceSmartOS.DataSourceSmartOS'>
2018-11-29 22:18:46,230 - util.py[DEBUG]: Running command ['systemd-detect-virt', '--quiet', '--container'] with allowed return codes [0] (shell=False, capture=True)
2018-11-29 22:18:46,231 - util.py[DEBUG]: Running command ['running-in-container'] with allowed return codes [0] (shell=False, capture=True)
2018-11-29 22:18:46,232 - util.py[DEBUG]: Running command ['lxc-is-container'] with allowed return codes [0] (shell=False, capture=True)
2018-11-29 22:18:46,234 - util.py[DEBUG]: Reading from /proc/1/environ (quiet=False)
2018-11-29 22:18:46,234 - util.py[DEBUG]: Read 150 bytes from /proc/1/environ
2018-11-29 22:18:46,234 - util.py[DEBUG]: Reading from /proc/self/status (quiet=False)
2018-11-29 22:18:46,234 - util.py[DEBUG]: Read 966 bytes from /proc/self/status
2018-11-29 22:18:46,234 - util.py[DEBUG]: querying dmi data /sys/class/dmi/id/product_name
2018-11-29 22:18:46,234 - util.py[DEBUG]: Reading from /sys/class/dmi/id/product_name (quiet=False)
2018-11-29 22:18:46,234 - util.py[DEBUG]: Read 9 bytes from /sys/class/dmi/id/product_name
2018-11-29 22:18:46,234 - util.py[DEBUG]: dmi data /sys/class/dmi/id/product_name returned HVM domU
2018-11-29 22:18:46,235 - __init__.py[DEBUG]: Update datasource metadata and network config due to events: New instance first boot
2018-11-29 22:18:46,235 - DataSourceSmartOS.py[DEBUG]: Not running on smartos
2018-11-29 22:18:46,235 - handlers.py[DEBUG]: finish: init-local/search-SmartOS: SUCCESS: no local data found from DataSourceSmartOS
2018-11-29 22:18:46,235 - handlers.py[DEBUG]: start: init-local/search-Ec2Local: searching for local data from DataSourceEc2Local
2018-11-29 22:18:46,235 - __init__.py[DEBUG]: Seeing if we can get any data from <class 'cloudinit.sources.DataSourceEc2.DataSourceEc2Local'>
2018-11-29 22:18:46,235 - __init__.py[DEBUG]: Update datasource metadata and network config due to events: New instance first boot
2018-11-29 22:18:46,235 - util.py[DEBUG]: Reading from /sys/hypervisor/uuid (quiet=False)
2018-11-29 22:18:46,235 - util.py[DEBUG]: Read 37 bytes from /sys/hypervisor/uuid
2018-11-29 22:18:46,235 - util.py[DEBUG]: Running command ['systemd-detect-virt', '--quiet', '--container'] with allowed return codes [0] (shell=False, capture=True)
2018-11-29 22:18:46,237 - util.py[DEBUG]: Running command ['running-in-container'] with allowed return codes [0] (shell=False, capture=True)
2018-11-29 22:18:46,238 - util.py[DEBUG]: Running command ['lxc-is-container'] with allowed return codes [0] (shell=False, capture=True)
2018-11-29 22:18:46,240 - util.py[DEBUG]: Reading from /proc/1/environ (quiet=False)
2018-11-29 22:18:46,240 - util.py[DEBUG]: Read 150 bytes from /proc/1/environ
2018-11-29 22:18:46,241 - util.py[DEBUG]: Reading from /proc/self/status (quiet=False)
2018-11-29 22:18:46,241 - util.py[DEBUG]: Read 966 bytes from /proc/self/status
2018-11-29 22:18:46,241 - util.py[DEBUG]: querying dmi data /sys/class/dmi/id/product_serial
2018-11-29 22:18:46,241 - util.py[DEBUG]: Reading from /sys/class/dmi/id/product_serial (quiet=False)
2018-11-29 22:18:46,241 - util.py[DEBUG]: Read 37 bytes from /sys/class/dmi/id/product_serial
2018-11-29 22:18:46,241 - util.py[DEBUG]: dmi data /sys/class/dmi/id/product_serial returned ec2858ca-12b8-2dcb-fc7e-893f50609c10
2018-11-29 22:18:46,241 - DataSourceEc2.py[DEBUG]: strict_mode: warn, cloud_platform=AWS
2018-11-29 22:18:46,241 - util.py[DEBUG]: Reading from /etc/os-release (quiet=False)
2018-11-29 22:18:46,241 - util.py[DEBUG]: Read 298 bytes from /etc/os-release
2018-11-29 22:18:46,242 - util.py[DEBUG]: Reading from /sys/class/net/ens3/name_assign_type (quiet=False)
2018-11-29 22:18:46,242 - util.py[DEBUG]: Read 2 bytes from /sys/class/net/ens3/name_assign_type
2018-11-29 22:18:46,242 - util.py[DEBUG]: Reading from /sys/class/net/ens3/carrier (quiet=False)
2018-11-29 22:18:46,242 - util.py[DEBUG]: Reading from /sys/class/net/ens3/dormant (quiet=False)
2018-11-29 22:18:46,242 - util.py[DEBUG]: Reading from /sys/class/net/ens3/operstate (quiet=False)
2018-11-29 22:18:46,242 - util.py[DEBUG]: Read 5 bytes from /sys/class/net/ens3/operstate
2018-11-29 22:18:46,242 - util.py[DEBUG]: Reading from /sys/class/net/ens3/address (quiet=False)
2018-11-29 22:18:46,242 - util.py[DEBUG]: Read 18 bytes from /sys/class/net/ens3/address
2018-11-29 22:18:46,243 - dhcp.py[DEBUG]: Performing a dhcp discovery on ens3
2018-11-29 22:18:46,243 - util.py[DEBUG]: Copying /sbin/dhclient to /var/tmp/cloud-init/cloud-init-dhcp-6kpo1rs1/dhclient
2018-11-29 22:18:46,257 - util.py[DEBUG]: Running command ['ip', 'link', 'set', 'dev', 'ens3', 'up'] with allowed return codes [0] (shell=False, capture=True)
2018-11-29 22:18:46,275 - util.py[DEBUG]: Running command ['/var/tmp/cloud-init/cloud-init-dhcp-6kpo1rs1/dhclient', '-1', '-v', '-lf', '/var/tmp/cloud-init/cloud-init-dhcp-6kpo1rs1/dhcp.leases', '-pf', '/var/tmp/cloud-init/cloud-init-dhcp-6kpo1rs1/dhclient.pid', 'ens3', '-sf', '/bin/true'] with allowed return codes [0] (shell=False, capture=True)
2018-11-29 22:18:46,352 - util.py[DEBUG]: All files appeared after 0 seconds: ['/var/tmp/cloud-init/cloud-init-dhcp-6kpo1rs1/dhclient.pid', '/var/tmp/cloud-init/cloud-init-dhcp-6kpo1rs1/dhcp.leases']
2018-11-29 22:18:46,352 - util.py[DEBUG]: Reading from /var/tmp/cloud-init/cloud-init-dhcp-6kpo1rs1/dhclient.pid (quiet=False)
2018-11-29 22:18:46,352 - util.py[DEBUG]: Read 5 bytes from /var/tmp/cloud-init/cloud-init-dhcp-6kpo1rs1/dhclient.pid
2018-11-29 22:18:46,353 - util.py[DEBUG]: Reading from /var/tmp/cloud-init/cloud-init-dhcp-6kpo1rs1/dhcp.leases (quiet=False)
2018-11-29 22:18:46,353 - util.py[DEBUG]: Read 516 bytes from /var/tmp/cloud-init/cloud-init-dhcp-6kpo1rs1/dhcp.leases
2018-11-29 22:18:46,353 - dhcp.py[DEBUG]: Received dhcp lease on ens3 for 10.0.0.188/255.255.255.0
2018-11-29 22:18:46,353 - __init__.py[DEBUG]: Attempting setup of ephemeral network on ens3 with 10.0.0.188/24 brd 10.0.0.255
2018-11-29 22:18:46,353 - util.py[DEBUG]: Running command ['ip', '-family', 'inet', 'addr', 'add', '10.0.0.188/24', 'broadcast', '10.0.0.255', 'dev', 'ens3'] with allowed return codes [0] (shell=False, capture=True)
2018-11-29 22:18:46,355 - util.py[DEBUG]: Running command ['ip', '-family', 'inet', 'link', 'set', 'dev', 'ens3', 'up'] with allowed return codes [0] (shell=False, capture=True)
2018-11-29 22:18:46,358 - util.py[DEBUG]: Running command ['ip', 'route', 'show', '0.0.0.0/0'] with allowed return codes [0] (shell=False, capture=True)
2018-11-29 22:18:46,360 - util.py[DEBUG]: Running command ['ip', '-4', 'route', 'add', 'default', 'via', '10.0.0.1', 'dev', 'ens3'] with allowed return codes [0] (shell=False, capture=True)
2018-11-29 22:18:46,364 - util.py[DEBUG]: Resolving URL: http://169.254.169.254 took 0.003 seconds
2018-11-29 22:18:46,365 - util.py[DEBUG]: Resolving URL: http://instance-data.:8773 took 0.000 seconds
2018-11-29 22:18:46,365 - DataSourceEc2.py[DEBUG]: Removed the following from metadata urls: ['http://instance-data.:8773']
2018-11-29 22:18:46,365 - url_helper.py[DEBUG]: [0/1] open 'http://169.254.169.254/2009-04-04/meta-data/instance-id' with {'timeout': 50.0, 'method': 'GET', 'headers': {'User-Agent': 'Cloud-Init/18.3-9-g2e62cb8a-0ubuntu1~16.04.2'}, 'url': 'http://169.254.169.254/2009-04-04/meta-data/instance-id', 'allow_redirects': True} configuration
2018-11-29 22:18:46,369 - url_helper.py[DEBUG]: Read from http://169.254.169.254/2009-04-04/meta-data/instance-id (200, 19b) after 1 attempts
2018-11-29 22:18:46,369 - DataSourceEc2.py[DEBUG]: Using metadata source: 'http://169.254.169.254'
2018-11-29 22:18:46,369 - url_helper.py[DEBUG]: [0/1] open 'http://169.254.169.254/2016-09-02/meta-data/instance-id' with {'method': 'GET', 'headers': {'User-Agent': 'Cloud-Init/18.3-9-g2e62cb8a-0ubuntu1~16.04.2'}, 'url': 'http://169.254.169.254/2016-09-02/meta-data/instance-id', 'allow_redirects': True} configuration
2018-11-29 22:18:46,371 - url_helper.py[DEBUG]: Read from http://169.254.169.254/2016-09-02/meta-data/instance-id (200, 19b) after 1 attempts
2018-11-29 22:18:46,371 - DataSourceEc2.py[DEBUG]: Found preferred metadata version 2016-09-02
2018-11-29 22:18:46,371 - url_helper.py[DEBUG]: [0/6] open 'http://169.254.169.254/2016-09-02/user-data' with {'timeout': 5.0, 'method': 'GET', 'headers': {'User-Agent': 'Cloud-Init/18.3-9-g2e62cb8a-0ubuntu1~16.04.2'}, 'url': 'http://169.254.169.254/2016-09-02/user-data', 'allow_redirects': True} configuration
2018-11-29 22:18:46,373 - url_helper.py[DEBUG]: [0/6] open 'http://169.254.169.254/2016-09-02/meta-data/' with {'timeout': 5.0, 'method': 'GET', 'headers': {'User-Agent': 'Cloud-Init/18.3-9-g2e62cb8a-0ubuntu1~16.04.2'}, 'url': 'http://169.254.169.254/2016-09-02/meta-data/', 'allow_redirects': True} configuration
2018-11-29 22:18:46,374 - url_helper.py[DEBUG]: Read from http://169.254.169.254/2016-09-02/meta-data/ (200, 268b) after 1 attempts
2018-11-29 22:18:46,374 - url_helper.py[DEBUG]: [0/6] open 'http://169.254.169.254/2016-09-02/meta-data/block-device-mapping/' with {'timeout': 5.0, 'method': 'GET', 'headers': {'User-Agent': 'Cloud-Init/18.3-9-g2e62cb8a-0ubuntu1~16.04.2'}, 'url': 'http://169.254.169.254/2016-09-02/meta-data/block-device-mapping/', 'allow_redirects': True} configuration
2018-11-29 22:18:46,376 - url_helper.py[DEBUG]: Read from http://169.254.169.254/2016-09-02/meta-data/block-device-mapping/ (200, 30b) after 1 attempts
2018-11-29 22:18:46,376 - url_helper.py[DEBUG]: [0/6] open 'http://169.254.169.254/2016-09-02/meta-data/block-device-mapping/ephemeral1' with {'timeout': 5.0, 'method': 'GET', 'headers': {'User-Agent': 'Cloud-Init/18.3-9-g2e62cb8a-0ubuntu1~16.04.2'}, 'url': 'http://169.254.169.254/2016-09-02/meta-data/block-device-mapping/ephemeral1', 'allow_redirects': True} configuration
2018-11-29 22:18:46,377 - url_helper.py[DEBUG]: Read from http://169.254.169.254/2016-09-02/meta-data/block-device-mapping/ephemeral1 (200, 3b) after 1 attempts
2018-11-29 22:18:46,378 - url_helper.py[DEBUG]: [0/6] open 'http://169.254.169.254/2016-09-02/meta-data/block-device-mapping/root' with {'timeout': 5.0, 'method': 'GET', 'headers': {'User-Agent': 'Cloud-Init/18.3-9-g2e62cb8a-0ubuntu1~16.04.2'}, 'url': 'http://169.254.169.254/2016-09-02/meta-data/block-device-mapping/root', 'allow_redirects': True} configuration
2018-11-29 22:18:46,379 - url_helper.py[DEBUG]: Read from http://169.254.169.254/2016-09-02/meta-data/block-device-mapping/root (200, 9b) after 1 attempts
2018-11-29 22:18:46,379 - url_helper.py[DEBUG]: [0/6] open 'http://169.254.169.254/2016-09-02/meta-data/block-device-mapping/ephemeral0' with {'timeout': 5.0, 'method': 'GET', 'headers': {'User-Agent': 'Cloud-Init/18.3-9-g2e62cb8a-0ubuntu1~16.04.2'}, 'url': 'http://169.254.169.254/2016-09-02/meta-data/block-device-mapping/ephemeral0', 'allow_redirects': True} configuration
2018-11-29 22:18:46,381 - url_helper.py[DEBUG]: Read from http://169.254.169.254/2016-09-02/meta-data/block-device-mapping/ephemeral0 (200, 3b) after 1 attempts
2018-11-29 22:18:46,381 - url_helper.py[DEBUG]: [0/6] open 'http://169.254.169.254/2016-09-02/meta-data/block-device-mapping/ami' with {'timeout': 5.0, 'method': 'GET', 'headers': {'User-Agent': 'Cloud-Init/18.3-9-g2e62cb8a-0ubuntu1~16.04.2'}, 'url': 'http://169.254.169.254/2016-09-02/meta-data/block-device-mapping/ami', 'allow_redirects': True} configuration
2018-11-29 22:18:46,382 - url_helper.py[DEBUG]: Read from http://169.254.169.254/2016-09-02/meta-data/block-device-mapping/ami (200, 9b) after 1 attempts
2018-11-29 22:18:46,382 - url_helper.py[DEBUG]: [0/6] open 'http://169.254.169.254/2016-09-02/meta-data/iam/' with {'timeout': 5.0, 'method': 'GET', 'headers': {'User-Agent': 'Cloud-Init/18.3-9-g2e62cb8a-0ubuntu1~16.04.2'}, 'url': 'http://169.254.169.254/2016-09-02/meta-data/iam/', 'allow_redirects': True} configuration
2018-11-29 22:18:46,384 - url_helper.py[DEBUG]: Read from http://169.254.169.254/2016-09-02/meta-data/iam/ (200, 26b) after 1 attempts
2018-11-29 22:18:46,384 - url_helper.py[DEBUG]: [0/6] open 'http://169.254.169.254/2016-09-02/meta-data/iam/info' with {'timeout': 5.0, 'method': 'GET', 'headers': {'User-Agent': 'Cloud-Init/18.3-9-g2e62cb8a-0ubuntu1~16.04.2'}, 'url': 'http://169.254.169.254/2016-09-02/meta-data/iam/info', 'allow_redirects': True} configuration
2018-11-29 22:18:46,385 - url_helper.py[DEBUG]: Read from http://169.254.169.254/2016-09-02/meta-data/iam/info (200, 246b) after 1 attempts
2018-11-29 22:18:46,386 - url_helper.py[DEBUG]: [0/6] open 'http://169.254.169.254/2016-09-02/meta-data/metrics/' with {'timeout': 5.0, 'method': 'GET', 'headers': {'User-Agent': 'Cloud-Init/18.3-9-g2e62cb8a-0ubuntu1~16.04.2'}, 'url': 'http://169.254.169.254/2016-09-02/meta-data/metrics/', 'allow_redirects': True} configuration
2018-11-29 22:18:46,387 - url_helper.py[DEBUG]: Read from http://169.254.169.254/2016-09-02/meta-data/metrics/ (200, 7b) after 1 attempts
2018-11-29 22:18:46,387 - url_helper.py[DEBUG]: [0/6] open 'http://169.254.169.254/2016-09-02/meta-data/metrics/vhostmd' with {'timeout': 5.0, 'method': 'GET', 'headers': {'User-Agent': 'Cloud-Init/18.3-9-g2e62cb8a-0ubuntu1~16.04.2'}, 'url': 'http://169.254.169.254/2016-09-02/meta-data/metrics/vhostmd', 'allow_redirects': True} configuration
2018-11-29 22:18:46,389 - url_helper.py[DEBUG]: Read from http://169.254.169.254/2016-09-02/meta-data/metrics/vhostmd (200, 38b) after 1 attempts
2018-11-29 22:18:46,389 - url_helper.py[DEBUG]: [0/6] open 'http://169.254.169.254/2016-09-02/meta-data/network/' with {'timeout': 5.0, 'method': 'GET', 'headers': {'User-Agent': 'Cloud-Init/18.3-9-g2e62cb8a-0ubuntu1~16.04.2'}, 'url': 'http://169.254.169.254/2016-09-02/meta-data/network/', 'allow_redirects': True} configuration
2018-11-29 22:18:46,390 - url_helper.py[DEBUG]: Read from http://169.254.169.254/2016-09-02/meta-data/network/ (200, 11b) after 1 attempts
2018-11-29 22:18:46,390 - url_helper.py[DEBUG]: [0/6] open 'http://169.254.169.254/2016-09-02/meta-data/network/interfaces/' with {'timeout': 5.0, 'method': 'GET', 'headers': {'User-Agent': 'Cloud-Init/18.3-9-g2e62cb8a-0ubuntu1~16.04.2'}, 'url': 'http://169.254.169.254/2016-09-02/meta-data/network/interfaces/', 'allow_redirects': True} configuration
2018-11-29 22:18:46,392 - url_helper.py[DEBUG]: Read from http://169.254.169.254/2016-09-02/meta-data/network/interfaces/ (200, 5b) after 1 attempts
2018-11-29 22:18:46,392 - url_helper.py[DEBUG]: [0/6] open 'http://169.254.169.254/2016-09-02/meta-data/network/interfaces/macs/' with {'timeout': 5.0, 'method': 'GET', 'headers': {'User-Agent': 'Cloud-Init/18.3-9-g2e62cb8a-0ubuntu1~16.04.2'}, 'url': 'http://169.254.169.254/2016-09-02/meta-data/network/interfaces/macs/', 'allow_redirects': True} configuration
2018-11-29 22:18:46,394 - url_helper.py[DEBUG]: Read from http://169.254.169.254/2016-09-02/meta-data/network/interfaces/macs/ (200, 18b) after 1 attempts
2018-11-29 22:18:46,394 - url_helper.py[DEBUG]: [0/6] open 'http://169.254.169.254/2016-09-02/meta-data/network/interfaces/macs/02:91:e1:a5:f7:d8/' with {'timeout': 5.0, 'method': 'GET', 'headers': {'User-Agent': 'Cloud-Init/18.3-9-g2e62cb8a-0ubuntu1~16.04.2'}, 'url': 'http://169.254.169.254/2016-09-02/meta-data/network/interfaces/macs/02:91:e1:a5:f7:d8/', 'allow_redirects': True} configuration
2018-11-29 22:18:46,395 - url_helper.py[DEBUG]: Read from http://169.254.169.254/2016-09-02/meta-data/network/interfaces/macs/02:91:e1:a5:f7:d8/ (200, 230b) after 1 attempts
2018-11-29 22:18:46,395 - url_helper.py[DEBUG]: [0/6] open 'http://169.254.169.254/2016-09-02/meta-data/network/interfaces/macs/02:91:e1:a5:f7:d8/ipv4-associations/' with {'timeout': 5.0, 'method': 'GET', 'headers': {'User-Agent': 'Cloud-Init/18.3-9-g2e62cb8a-0ubuntu1~16.04.2'}, 'url': 'http://169.254.169.254/2016-09-02/meta-data/network/interfaces/macs/02:91:e1:a5:f7:d8/ipv4-associations/', 'allow_redirects': True} configuration
2018-11-29 22:18:46,397 - url_helper.py[DEBUG]: Read from http://169.254.169.254/2016-09-02/meta-data/network/interfaces/macs/02:91:e1:a5:f7:d8/ipv4-associations/ (200, 14b) after 1 attempts
2018-11-29 22:18:46,397 - url_helper.py[DEBUG]: [0/6] open 'http://169.254.169.254/2016-09-02/meta-data/network/interfaces/macs/02:91:e1:a5:f7:d8/ipv4-associations/18.196.241.115' with {'timeout': 5.0, 'method': 'GET', 'headers': {'User-Agent': 'Cloud-Init/18.3-9-g2e62cb8a-0ubuntu1~16.04.2'}, 'url': 'http://169.254.169.254/2016-09-02/meta-data/network/interfaces/macs/02:91:e1:a5:f7:d8/ipv4-associations/18.196.241.115', 'allow_redirects': True} configuration
2018-11-29 22:18:46,398 - url_helper.py[DEBUG]: Read from http://169.254.169.254/2016-09-02/meta-data/network/interfaces/macs/02:91:e1:a5:f7:d8/ipv4-associations/18.196.241.115 (200, 10b) after 1 attempts
2018-11-29 22:18:46,399 - url_helper.py[DEBUG]: [0/6] open 'http://169.254.169.254/2016-09-02/meta-data/network/interfaces/macs/02:91:e1:a5:f7:d8/device-number' with {'timeout': 5.0, 'method': 'GET', 'headers': {'User-Agent': 'Cloud-Init/18.3-9-g2e62cb8a-0ubuntu1~16.04.2'}, 'url': 'http://169.254.169.254/2016-09-02/meta-data/network/interfaces/macs/02:91:e1:a5:f7:d8/device-number', 'allow_redirects': True} configuration
2018-11-29 22:18:46,400 - url_helper.py[DEBUG]: Read from http://169.254.169.254/2016-09-02/meta-data/network/interfaces/macs/02:91:e1:a5:f7:d8/device-number (200, 1b) after 1 attempts
2018-11-29 22:18:46,400 - url_helper.py[DEBUG]: [0/6] open 'http://169.254.169.254/2016-09-02/meta-data/network/interfaces/macs/02:91:e1:a5:f7:d8/subnet-id' with {'timeout': 5.0, 'method': 'GET', 'headers': {'User-Agent': 'Cloud-Init/18.3-9-g2e62cb8a-0ubuntu1~16.04.2'}, 'url': 'http://169.254.169.254/2016-09-02/meta-data/network/interfaces/macs/02:91:e1:a5:f7:d8/subnet-id', 'allow_redirects': True} configuration
2018-11-29 22:18:46,402 - url_helper.py[DEBUG]: Read from http://169.254.169.254/2016-09-02/meta-data/network/interfaces/macs/02:91:e1:a5:f7:d8/subnet-id (200, 24b) after 1 attempts
2018-11-29 22:18:46,402 - url_helper.py[DEBUG]: [0/6] open 'http://169.254.169.254/2016-09-02/meta-data/network/interfaces/macs/02:91:e1:a5:f7:d8/mac' with {'timeout': 5.0, 'method': 'GET', 'headers': {'User-Agent': 'Cloud-Init/18.3-9-g2e62cb8a-0ubuntu1~16.04.2'}, 'url': 'http://169.254.169.254/2016-09-02/meta-data/network/interfaces/macs/02:91:e1:a5:f7:d8/mac', 'allow_redirects': True} configuration
2018-11-29 22:18:46,403 - url_helper.py[DEBUG]: Read from http://169.254.169.254/2016-09-02/meta-data/network/interfaces/macs/02:91:e1:a5:f7:d8/mac (200, 17b) after 1 attempts
2018-11-29 22:18:46,403 - url_helper.py[DEBUG]: [0/6] open 'http://169.254.169.254/2016-09-02/meta-data/network/interfaces/macs/02:91:e1:a5:f7:d8/security-group-ids' with {'timeout': 5.0, 'method': 'GET', 'headers': {'User-Agent': 'Cloud-Init/18.3-9-g2e62cb8a-0ubuntu1~16.04.2'}, 'url': 'http://169.254.169.254/2016-09-02/meta-data/network/interfaces/macs/02:91:e1:a5:f7:d8/security-group-ids', 'allow_redirects': True} configuration
2018-11-29 22:18:46,405 - url_helper.py[DEBUG]: Read from http://169.254.169.254/2016-09-02/meta-data/network/interfaces/macs/02:91:e1:a5:f7:d8/security-group-ids (200, 83b) after 1 attempts
2018-11-29 22:18:46,405 - url_helper.py[DEBUG]: [0/6] open 'http://169.254.169.254/2016-09-02/meta-data/network/interfaces/macs/02:91:e1:a5:f7:d8/owner-id' with {'timeout': 5.0, 'method': 'GET', 'headers': {'User-Agent': 'Cloud-Init/18.3-9-g2e62cb8a-0ubuntu1~16.04.2'}, 'url': 'http://169.254.169.254/2016-09-02/meta-data/network/interfaces/macs/02:91:e1:a5:f7:d8/owner-id', 'allow_redirects': True} configuration
2018-11-29 22:18:46,407 - url_helper.py[DEBUG]: Read from http://169.254.169.254/2016-09-02/meta-data/network/interfaces/macs/02:91:e1:a5:f7:d8/owner-id (200, 12b) after 1 attempts
2018-11-29 22:18:46,407 - url_helper.py[DEBUG]: [0/6] open 'http://169.254.169.254/2016-09-02/meta-data/network/interfaces/macs/02:91:e1:a5:f7:d8/public-ipv4s' with {'timeout': 5.0, 'method': 'GET', 'headers': {'User-Agent': 'Cloud-Init/18.3-9-g2e62cb8a-0ubuntu1~16.04.2'}, 'url': 'http://169.254.169.254/2016-09-02/meta-data/network/interfaces/macs/02:91:e1:a5:f7:d8/public-ipv4s', 'allow_redirects': True} configuration
2018-11-29 22:18:46,408 - url_helper.py[DEBUG]: Read from http://169.254.169.254/2016-09-02/meta-data/network/interfaces/macs/02:91:e1:a5:f7:d8/public-ipv4s (200, 14b) after 1 attempts
2018-11-29 22:18:46,409 - url_helper.py[DEBUG]: [0/6] open 'http://169.254.169.254/2016-09-02/meta-data/network/interfaces/macs/02:91:e1:a5:f7:d8/local-ipv4s' with {'timeout': 5.0, 'method': 'GET', 'headers': {'User-Agent': 'Cloud-Init/18.3-9-g2e62cb8a-0ubuntu1~16.04.2'}, 'url': 'http://169.254.169.254/2016-09-02/meta-data/network/interfaces/macs/02:91:e1:a5:f7:d8/local-ipv4s', 'allow_redirects': True} configuration
2018-11-29 22:18:46,410 - url_helper.py[DEBUG]: Read from http://169.254.169.254/2016-09-02/meta-data/network/interfaces/macs/02:91:e1:a5:f7:d8/local-ipv4s (200, 10b) after 1 attempts
2018-11-29 22:18:46,410 - url_helper.py[DEBUG]: [0/6] open 'http://169.254.169.254/2016-09-02/meta-data/network/interfaces/macs/02:91:e1:a5:f7:d8/local-hostname' with {'timeout': 5.0, 'method': 'GET', 'headers': {'User-Agent': 'Cloud-Init/18.3-9-g2e62cb8a-0ubuntu1~16.04.2'}, 'url': 'http://169.254.169.254/2016-09-02/meta-data/network/interfaces/macs/02:91:e1:a5:f7:d8/local-hostname', 'allow_redirects': True} configuration
2018-11-29 22:18:46,413 - url_helper.py[DEBUG]: Read from http://169.254.169.254/2016-09-02/meta-data/network/interfaces/macs/02:91:e1:a5:f7:d8/local-hostname (200, 43b) after 1 attempts
2018-11-29 22:18:46,413 - url_helper.py[DEBUG]: [0/6] open 'http://169.254.169.254/2016-09-02/meta-data/network/interfaces/macs/02:91:e1:a5:f7:d8/vpc-ipv4-cidr-blocks' with {'timeout': 5.0, 'method': 'GET', 'headers': {'User-Agent': 'Cloud-Init/18.3-9-g2e62cb8a-0ubuntu1~16.04.2'}, 'url': 'http://169.254.169.254/2016-09-02/meta-data/network/interfaces/macs/02:91:e1:a5:f7:d8/vpc-ipv4-cidr-blocks', 'allow_redirects': True} configuration
2018-11-29 22:18:46,414 - url_helper.py[DEBUG]: Read from http://169.254.169.254/2016-09-02/meta-data/network/interfaces/macs/02:91:e1:a5:f7:d8/vpc-ipv4-cidr-blocks (200, 11b) after 1 attempts
2018-11-29 22:18:46,414 - url_helper.py[DEBUG]: [0/6] open 'http://169.254.169.254/2016-09-02/meta-data/network/interfaces/macs/02:91:e1:a5:f7:d8/interface-id' with {'timeout': 5.0, 'method': 'GET', 'headers': {'User-Agent': 'Cloud-Init/18.3-9-g2e62cb8a-0ubuntu1~16.04.2'}, 'url': 'http://169.254.169.254/2016-09-02/meta-data/network/interfaces/macs/02:91:e1:a5:f7:d8/interface-id', 'allow_redirects': True} configuration
2018-11-29 22:18:46,416 - url_helper.py[DEBUG]: Read from http://169.254.169.254/2016-09-02/meta-data/network/interfaces/macs/02:91:e1:a5:f7:d8/interface-id (200, 21b) after 1 attempts
2018-11-29 22:18:46,416 - url_helper.py[DEBUG]: [0/6] open 'http://169.254.169.254/2016-09-02/meta-data/network/interfaces/macs/02:91:e1:a5:f7:d8/vpc-ipv4-cidr-block' with {'timeout': 5.0, 'method': 'GET', 'headers': {'User-Agent': 'Cloud-Init/18.3-9-g2e62cb8a-0ubuntu1~16.04.2'}, 'url': 'http://169.254.169.254/2016-09-02/meta-data/network/interfaces/macs/02:91:e1:a5:f7:d8/vpc-ipv4-cidr-block', 'allow_redirects': True} configuration
2018-11-29 22:18:46,417 - url_helper.py[DEBUG]: Read from http://169.254.169.254/2016-09-02/meta-data/network/interfaces/macs/02:91:e1:a5:f7:d8/vpc-ipv4-cidr-block (200, 11b) after 1 attempts
2018-11-29 22:18:46,418 - url_helper.py[DEBUG]: [0/6] open 'http://169.254.169.254/2016-09-02/meta-data/network/interfaces/macs/02:91:e1:a5:f7:d8/public-hostname' with {'timeout': 5.0, 'method': 'GET', 'headers': {'User-Agent': 'Cloud-Init/18.3-9-g2e62cb8a-0ubuntu1~16.04.2'}, 'url': 'http://169.254.169.254/2016-09-02/meta-data/network/interfaces/macs/02:91:e1:a5:f7:d8/public-hostname', 'allow_redirects': True} configuration
2018-11-29 22:18:46,419 - url_helper.py[DEBUG]: Read from http://169.254.169.254/2016-09-02/meta-data/network/interfaces/macs/02:91:e1:a5:f7:d8/public-hostname (200, 53b) after 1 attempts
2018-11-29 22:18:46,419 - url_helper.py[DEBUG]: [0/6] open 'http://169.254.169.254/2016-09-02/meta-data/network/interfaces/macs/02:91:e1:a5:f7:d8/security-groups' with {'timeout': 5.0, 'method': 'GET', 'headers': {'User-Agent': 'Cloud-Init/18.3-9-g2e62cb8a-0ubuntu1~16.04.2'}, 'url': 'http://169.254.169.254/2016-09-02/meta-data/network/interfaces/macs/02:91:e1:a5:f7:d8/security-groups', 'allow_redirects': True} configuration
2018-11-29 22:18:46,421 - url_helper.py[DEBUG]: Read from http://169.254.169.254/2016-09-02/meta-data/network/interfaces/macs/02:91:e1:a5:f7:d8/security-groups (200, 326b) after 1 attempts
2018-11-29 22:18:46,421 - url_helper.py[DEBUG]: [0/6] open 'http://169.254.169.254/2016-09-02/meta-data/network/interfaces/macs/02:91:e1:a5:f7:d8/subnet-ipv4-cidr-block' with {'timeout': 5.0, 'method': 'GET', 'headers': {'User-Agent': 'Cloud-Init/18.3-9-g2e62cb8a-0ubuntu1~16.04.2'}, 'url': 'http://169.254.169.254/2016-09-02/meta-data/network/interfaces/macs/02:91:e1:a5:f7:d8/subnet-ipv4-cidr-block', 'allow_redirects': True} configuration
2018-11-29 22:18:46,422 - url_helper.py[DEBUG]: Read from http://169.254.169.254/2016-09-02/meta-data/network/interfaces/macs/02:91:e1:a5:f7:d8/subnet-ipv4-cidr-block (200, 11b) after 1 attempts
2018-11-29 22:18:46,422 - url_helper.py[DEBUG]: [0/6] open 'http://169.254.169.254/2016-09-02/meta-data/network/interfaces/macs/02:91:e1:a5:f7:d8/vpc-id' with {'timeout': 5.0, 'method': 'GET', 'headers': {'User-Agent': 'Cloud-Init/18.3-9-g2e62cb8a-0ubuntu1~16.04.2'}, 'url': 'http://169.254.169.254/2016-09-02/meta-data/network/interfaces/macs/02:91:e1:a5:f7:d8/vpc-id', 'allow_redirects': True} configuration
2018-11-29 22:18:46,424 - url_helper.py[DEBUG]: Read from http://169.254.169.254/2016-09-02/meta-data/network/interfaces/macs/02:91:e1:a5:f7:d8/vpc-id (200, 21b) after 1 attempts
2018-11-29 22:18:46,424 - url_helper.py[DEBUG]: [0/6] open 'http://169.254.169.254/2016-09-02/meta-data/placement/' with {'timeout': 5.0, 'method': 'GET', 'headers': {'User-Agent': 'Cloud-Init/18.3-9-g2e62cb8a-0ubuntu1~16.04.2'}, 'url': 'http://169.254.169.254/2016-09-02/meta-data/placement/', 'allow_redirects': True} configuration
2018-11-29 22:18:46,425 - url_helper.py[DEBUG]: Read from http://169.254.169.254/2016-09-02/meta-data/placement/ (200, 17b) after 1 attempts
2018-11-29 22:18:46,426 - url_helper.py[DEBUG]: [0/6] open 'http://169.254.169.254/2016-09-02/meta-data/placement/availability-zone' with {'timeout': 5.0, 'method': 'GET', 'headers': {'User-Agent': 'Cloud-Init/18.3-9-g2e62cb8a-0ubuntu1~16.04.2'}, 'url': 'http://169.254.169.254/2016-09-02/meta-data/placement/availability-zone', 'allow_redirects': True} configuration
2018-11-29 22:18:46,427 - url_helper.py[DEBUG]: Read from http://169.254.169.254/2016-09-02/meta-data/placement/availability-zone (200, 13b) after 1 attempts
2018-11-29 22:18:46,427 - url_helper.py[DEBUG]: [0/6] open 'http://169.254.169.254/2016-09-02/meta-data/public-keys/' with {'timeout': 5.0, 'method': 'GET', 'headers': {'User-Agent': 'Cloud-Init/18.3-9-g2e62cb8a-0ubuntu1~16.04.2'}, 'url': 'http://169.254.169.254/2016-09-02/meta-data/public-keys/', 'allow_redirects': True} configuration
2018-11-29 22:18:46,428 - url_helper.py[DEBUG]: Read from http://169.254.169.254/2016-09-02/meta-data/public-keys/ (200, 68b) after 1 attempts
2018-11-29 22:18:46,429 - url_helper.py[DEBUG]: [0/6] open 'http://169.254.169.254/2016-09-02/meta-data/public-keys/0/openssh-key' with {'timeout': 5.0, 'method': 'GET', 'headers': {'User-Agent': 'Cloud-Init/18.3-9-g2e62cb8a-0ubuntu1~16.04.2'}, 'url': 'http://169.254.169.254/2016-09-02/meta-data/public-keys/0/openssh-key', 'allow_redirects': True} configuration
2018-11-29 22:18:46,430 - url_helper.py[DEBUG]: Read from http://169.254.169.254/2016-09-02/meta-data/public-keys/0/openssh-key (200, 448b) after 1 attempts
2018-11-29 22:18:46,430 - url_helper.py[DEBUG]: [0/6] open 'http://169.254.169.254/2016-09-02/meta-data/services/' with {'timeout': 5.0, 'method': 'GET', 'headers': {'User-Agent': 'Cloud-Init/18.3-9-g2e62cb8a-0ubuntu1~16.04.2'}, 'url': 'http://169.254.169.254/2016-09-02/meta-data/services/', 'allow_redirects': True} configuration
2018-11-29 22:18:46,432 - url_helper.py[DEBUG]: Read from http://169.254.169.254/2016-09-02/meta-data/services/ (200, 16b) after 1 attempts
2018-11-29 22:18:46,432 - url_helper.py[DEBUG]: [0/6] open 'http://169.254.169.254/2016-09-02/meta-data/services/domain' with {'timeout': 5.0, 'method': 'GET', 'headers': {'User-Agent': 'Cloud-Init/18.3-9-g2e62cb8a-0ubuntu1~16.04.2'}, 'url': 'http://169.254.169.254/2016-09-02/meta-data/services/domain', 'allow_redirects': True} configuration
2018-11-29 22:18:46,433 - url_helper.py[DEBUG]: Read from http://169.254.169.254/2016-09-02/meta-data/services/domain (200, 13b) after 1 attempts
2018-11-29 22:18:46,433 - url_helper.py[DEBUG]: [0/6] open 'http://169.254.169.254/2016-09-02/meta-data/services/partition' with {'timeout': 5.0, 'method': 'GET', 'headers': {'User-Agent': 'Cloud-Init/18.3-9-g2e62cb8a-0ubuntu1~16.04.2'}, 'url': 'http://169.254.169.254/2016-09-02/meta-data/services/partition', 'allow_redirects': True} configuration
2018-11-29 22:18:46,435 - url_helper.py[DEBUG]: Read from http://169.254.169.254/2016-09-02/meta-data/services/partition (200, 3b) after 1 attempts
2018-11-29 22:18:46,435 - url_helper.py[DEBUG]: [0/6] open 'http://169.254.169.254/2016-09-02/meta-data/local-hostname' with {'timeout': 5.0, 'method': 'GET', 'headers': {'User-Agent': 'Cloud-Init/18.3-9-g2e62cb8a-0ubuntu1~16.04.2'}, 'url': 'http://169.254.169.254/2016-09-02/meta-data/local-hostname', 'allow_redirects': True} configuration
2018-11-29 22:18:46,436 - url_helper.py[DEBUG]: Read from http://169.254.169.254/2016-09-02/meta-data/local-hostname (200, 43b) after 1 attempts
2018-11-29 22:18:46,437 - url_helper.py[DEBUG]: [0/6] open 'http://169.254.169.254/2016-09-02/meta-data/mac' with {'timeout': 5.0, 'method': 'GET', 'headers': {'User-Agent': 'Cloud-Init/18.3-9-g2e62cb8a-0ubuntu1~16.04.2'}, 'url': 'http://169.254.169.254/2016-09-02/meta-data/mac', 'allow_redirects': True} configuration
2018-11-29 22:18:46,438 - url_helper.py[DEBUG]: Read from http://169.254.169.254/2016-09-02/meta-data/mac (200, 17b) after 1 attempts
2018-11-29 22:18:46,438 - url_helper.py[DEBUG]: [0/6] open 'http://169.254.169.254/2016-09-02/meta-data/instance-action' with {'timeout': 5.0, 'method': 'GET', 'headers': {'User-Agent': 'Cloud-Init/18.3-9-g2e62cb8a-0ubuntu1~16.04.2'}, 'url': 'http://169.254.169.254/2016-09-02/meta-data/instance-action', 'allow_redirects': True} configuration
2018-11-29 22:18:46,439 - url_helper.py[DEBUG]: Read from http://169.254.169.254/2016-09-02/meta-data/instance-action (200, 4b) after 1 attempts
2018-11-29 22:18:46,440 - url_helper.py[DEBUG]: [0/6] open 'http://169.254.169.254/2016-09-02/meta-data/public-ipv4' with {'timeout': 5.0, 'method': 'GET', 'headers': {'User-Agent': 'Cloud-Init/18.3-9-g2e62cb8a-0ubuntu1~16.04.2'}, 'url': 'http://169.254.169.254/2016-09-02/meta-data/public-ipv4', 'allow_redirects': True} configuration
2018-11-29 22:18:46,441 - url_helper.py[DEBUG]: Read from http://169.254.169.254/2016-09-02/meta-data/public-ipv4 (200, 14b) after 1 attempts
2018-11-29 22:18:46,441 - url_helper.py[DEBUG]: [0/6] open 'http://169.254.169.254/2016-09-02/meta-data/local-ipv4' with {'timeout': 5.0, 'method': 'GET', 'headers': {'User-Agent': 'Cloud-Init/18.3-9-g2e62cb8a-0ubuntu1~16.04.2'}, 'url': 'http://169.254.169.254/2016-09-02/meta-data/local-ipv4', 'allow_redirects': True} configuration
2018-11-29 22:18:46,443 - url_helper.py[DEBUG]: Read from http://169.254.169.254/2016-09-02/meta-data/local-ipv4 (200, 10b) after 1 attempts
2018-11-29 22:18:46,443 - url_helper.py[DEBUG]: [0/6] open 'http://169.254.169.254/2016-09-02/meta-data/ami-manifest-path' with {'timeout': 5.0, 'method': 'GET', 'headers': {'User-Agent': 'Cloud-Init/18.3-9-g2e62cb8a-0ubuntu1~16.04.2'}, 'url': 'http://169.254.169.254/2016-09-02/meta-data/ami-manifest-path', 'allow_redirects': True} configuration
2018-11-29 22:18:46,444 - url_helper.py[DEBUG]: Read from http://169.254.169.254/2016-09-02/meta-data/ami-manifest-path (200, 9b) after 1 attempts
2018-11-29 22:18:46,445 - url_helper.py[DEBUG]: [0/6] open 'http://169.254.169.254/2016-09-02/meta-data/reservation-id' with {'timeout': 5.0, 'method': 'GET', 'headers': {'User-Agent': 'Cloud-Init/18.3-9-g2e62cb8a-0ubuntu1~16.04.2'}, 'url': 'http://169.254.169.254/2016-09-02/meta-data/reservation-id', 'allow_redirects': True} configuration
2018-11-29 22:18:46,446 - url_helper.py[DEBUG]: Read from http://169.254.169.254/2016-09-02/meta-data/reservation-id (200, 19b) after 1 attempts
2018-11-29 22:18:46,446 - url_helper.py[DEBUG]: [0/6] open 'http://169.254.169.254/2016-09-02/meta-data/ami-id' with {'timeout': 5.0, 'method': 'GET', 'headers': {'User-Agent': 'Cloud-Init/18.3-9-g2e62cb8a-0ubuntu1~16.04.2'}, 'url': 'http://169.254.169.254/2016-09-02/meta-data/ami-id', 'allow_redirects': True} configuration
2018-11-29 22:18:46,447 - url_helper.py[DEBUG]: Read from http://169.254.169.254/2016-09-02/meta-data/ami-id (200, 21b) after 1 attempts
2018-11-29 22:18:46,448 - url_helper.py[DEBUG]: [0/6] open 'http://169.254.169.254/2016-09-02/meta-data/public-hostname' with {'timeout': 5.0, 'method': 'GET', 'headers': {'User-Agent': 'Cloud-Init/18.3-9-g2e62cb8a-0ubuntu1~16.04.2'}, 'url': 'http://169.254.169.254/2016-09-02/meta-data/public-hostname', 'allow_redirects': True} configuration
2018-11-29 22:18:46,449 - url_helper.py[DEBUG]: Read from http://169.254.169.254/2016-09-02/meta-data/public-hostname (200, 53b) after 1 attempts
2018-11-29 22:18:46,449 - url_helper.py[DEBUG]: [0/6] open 'http://169.254.169.254/2016-09-02/meta-data/hostname' with {'timeout': 5.0, 'method': 'GET', 'headers': {'User-Agent': 'Cloud-Init/18.3-9-g2e62cb8a-0ubuntu1~16.04.2'}, 'url': 'http://169.254.169.254/2016-09-02/meta-data/hostname', 'allow_redirects': True} configuration
2018-11-29 22:18:46,450 - url_helper.py[DEBUG]: Read from http://169.254.169.254/2016-09-02/meta-data/hostname (200, 43b) after 1 attempts
2018-11-29 22:18:46,451 - url_helper.py[DEBUG]: [0/6] open 'http://169.254.169.254/2016-09-02/meta-data/security-groups' with {'timeout': 5.0, 'method': 'GET', 'headers': {'User-Agent': 'Cloud-Init/18.3-9-g2e62cb8a-0ubuntu1~16.04.2'}, 'url': 'http://169.254.169.254/2016-09-02/meta-data/security-groups', 'allow_redirects': True} configuration
2018-11-29 22:18:46,452 - url_helper.py[DEBUG]: Read from http://169.254.169.254/2016-09-02/meta-data/security-groups (200, 326b) after 1 attempts
2018-11-29 22:18:46,452 - url_helper.py[DEBUG]: [0/6] open 'http://169.254.169.254/2016-09-02/meta-data/profile' with {'timeout': 5.0, 'method': 'GET', 'headers': {'User-Agent': 'Cloud-Init/18.3-9-g2e62cb8a-0ubuntu1~16.04.2'}, 'url': 'http://169.254.169.254/2016-09-02/meta-data/profile', 'allow_redirects': True} configuration
2018-11-29 22:18:46,454 - url_helper.py[DEBUG]: Read from http://169.254.169.254/2016-09-02/meta-data/profile (200, 11b) after 1 attempts
2018-11-29 22:18:46,454 - url_helper.py[DEBUG]: [0/6] open 'http://169.254.169.254/2016-09-02/meta-data/ami-launch-index' with {'timeout': 5.0, 'method': 'GET', 'headers': {'User-Agent': 'Cloud-Init/18.3-9-g2e62cb8a-0ubuntu1~16.04.2'}, 'url': 'http://169.254.169.254/2016-09-02/meta-data/ami-launch-index', 'allow_redirects': True} configuration
2018-11-29 22:18:46,455 - url_helper.py[DEBUG]: Read from http://169.254.169.254/2016-09-02/meta-data/ami-launch-index (200, 1b) after 1 attempts
2018-11-29 22:18:46,455 - url_helper.py[DEBUG]: [0/6] open 'http://169.254.169.254/2016-09-02/meta-data/instance-id' with {'timeout': 5.0, 'method': 'GET', 'headers': {'User-Agent': 'Cloud-Init/18.3-9-g2e62cb8a-0ubuntu1~16.04.2'}, 'url': 'http://169.254.169.254/2016-09-02/meta-data/instance-id', 'allow_redirects': True} configuration
2018-11-29 22:18:46,457 - url_helper.py[DEBUG]: Read from http://169.254.169.254/2016-09-02/meta-data/instance-id (200, 19b) after 1 attempts
2018-11-29 22:18:46,457 - url_helper.py[DEBUG]: [0/6] open 'http://169.254.169.254/2016-09-02/meta-data/instance-type' with {'timeout': 5.0, 'method': 'GET', 'headers': {'User-Agent': 'Cloud-Init/18.3-9-g2e62cb8a-0ubuntu1~16.04.2'}, 'url': 'http://169.254.169.254/2016-09-02/meta-data/instance-type', 'allow_redirects': True} configuration
2018-11-29 22:18:46,458 - url_helper.py[DEBUG]: Read from http://169.254.169.254/2016-09-02/meta-data/instance-type (200, 10b) after 1 attempts
2018-11-29 22:18:46,459 - url_helper.py[DEBUG]: [0/6] open 'http://169.254.169.254/2016-09-02/dynamic/instance-identity' with {'timeout': 5.0, 'method': 'GET', 'headers': {'User-Agent': 'Cloud-Init/18.3-9-g2e62cb8a-0ubuntu1~16.04.2'}, 'url': 'http://169.254.169.254/2016-09-02/dynamic/instance-identity', 'allow_redirects': True} configuration
2018-11-29 22:18:46,461 - url_helper.py[DEBUG]: Read from http://169.254.169.254/2016-09-02/dynamic/instance-identity (200, 33b) after 1 attempts
2018-11-29 22:18:46,461 - url_helper.py[DEBUG]: [0/6] open 'http://169.254.169.254/2016-09-02/dynamic/instance-identity/pkcs7' with {'timeout': 5.0, 'method': 'GET', 'headers': {'User-Agent': 'Cloud-Init/18.3-9-g2e62cb8a-0ubuntu1~16.04.2'}, 'url': 'http://169.254.169.254/2016-09-02/dynamic/instance-identity/pkcs7', 'allow_redirects': True} configuration
2018-11-29 22:18:46,462 - url_helper.py[DEBUG]: Read from http://169.254.169.254/2016-09-02/dynamic/instance-identity/pkcs7 (200, 1126b) after 1 attempts
2018-11-29 22:18:46,463 - url_helper.py[DEBUG]: [0/6] open 'http://169.254.169.254/2016-09-02/dynamic/instance-identity/signature' with {'timeout': 5.0, 'method': 'GET', 'headers': {'User-Agent': 'Cloud-Init/18.3-9-g2e62cb8a-0ubuntu1~16.04.2'}, 'url': 'http://169.254.169.254/2016-09-02/dynamic/instance-identity/signature', 'allow_redirects': True} configuration
2018-11-29 22:18:46,464 - url_helper.py[DEBUG]: Read from http://169.254.169.254/2016-09-02/dynamic/instance-identity/signature (200, 174b) after 1 attempts
2018-11-29 22:18:46,464 - url_helper.py[DEBUG]: [0/6] open 'http://169.254.169.254/2016-09-02/dynamic/instance-identity/document' with {'timeout': 5.0, 'method': 'GET', 'headers': {'User-Agent': 'Cloud-Init/18.3-9-g2e62cb8a-0ubuntu1~16.04.2'}, 'url': 'http://169.254.169.254/2016-09-02/dynamic/instance-identity/document', 'allow_redirects': True} configuration
2018-11-29 22:18:46,466 - url_helper.py[DEBUG]: Read from http://169.254.169.254/2016-09-02/dynamic/instance-identity/document (200, 482b) after 1 attempts
2018-11-29 22:18:46,466 - url_helper.py[DEBUG]: [0/6] open 'http://169.254.169.254/2016-09-02/dynamic/instance-identity/rsa2048' with {'timeout': 5.0, 'method': 'GET', 'headers': {'User-Agent': 'Cloud-Init/18.3-9-g2e62cb8a-0ubuntu1~16.04.2'}, 'url': 'http://169.254.169.254/2016-09-02/dynamic/instance-identity/rsa2048', 'allow_redirects': True} configuration
2018-11-29 22:18:46,467 - url_helper.py[DEBUG]: Read from http://169.254.169.254/2016-09-02/dynamic/instance-identity/rsa2048 (200, 1442b) after 1 attempts
2018-11-29 22:18:46,468 - util.py[DEBUG]: Crawl of metadata service took 0.106 seconds
2018-11-29 22:18:46,468 - util.py[DEBUG]: Running command ['ip', '-4', 'route', 'del', 'default', 'dev', 'ens3'] with allowed return codes [0] (shell=False, capture=True)
2018-11-29 22:18:46,469 - util.py[DEBUG]: Running command ['ip', '-family', 'inet', 'link', 'set', 'dev', 'ens3', 'down'] with allowed return codes [0] (shell=False, capture=True)
2018-11-29 22:18:46,503 - util.py[DEBUG]: Running command ['ip', '-family', 'inet', 'addr', 'del', '10.0.0.188/24', 'dev', 'ens3'] with allowed return codes [0] (shell=False, capture=True)
2018-11-29 22:18:46,507 - handlers.py[DEBUG]: finish: init-local/search-Ec2Local: SUCCESS: found local data from DataSourceEc2Local
2018-11-29 22:18:46,507 - stages.py[INFO]: Loaded datasource DataSourceEc2Local - DataSourceEc2Local
2018-11-29 22:18:46,507 - util.py[DEBUG]: Reading from /etc/cloud/cloud.cfg (quiet=False)
2018-11-29 22:18:46,507 - util.py[DEBUG]: Read 3169 bytes from /etc/cloud/cloud.cfg
2018-11-29 22:18:46,507 - util.py[DEBUG]: Attempting to load yaml from string of length 3169 with allowed root types (<class 'dict'>,)
2018-11-29 22:18:46,518 - util.py[DEBUG]: Reading from /etc/cloud/cloud.cfg.d/90_dpkg.cfg (quiet=False)
2018-11-29 22:18:46,518 - util.py[DEBUG]: Read 238 bytes from /etc/cloud/cloud.cfg.d/90_dpkg.cfg
2018-11-29 22:18:46,518 - util.py[DEBUG]: Attempting to load yaml from string of length 238 with allowed root types (<class 'dict'>,)
2018-11-29 22:18:46,519 - util.py[DEBUG]: Reading from /etc/cloud/cloud.cfg.d/05_logging.cfg (quiet=False)
2018-11-29 22:18:46,520 - util.py[DEBUG]: Read 2057 bytes from /etc/cloud/cloud.cfg.d/05_logging.cfg
2018-11-29 22:18:46,520 - util.py[DEBUG]: Attempting to load yaml from string of length 2057 with allowed root types (<class 'dict'>,)
2018-11-29 22:18:46,523 - util.py[DEBUG]: Reading from /run/cloud-init/cloud.cfg (quiet=False)
2018-11-29 22:18:46,523 - util.py[DEBUG]: Read 44 bytes from /run/cloud-init/cloud.cfg
2018-11-29 22:18:46,523 - util.py[DEBUG]: Attempting to load yaml from string of length 44 with allowed root types (<class 'dict'>,)
2018-11-29 22:18:46,524 - util.py[DEBUG]: Attempting to load yaml from string of length 0 with allowed root types (<class 'dict'>,)
2018-11-29 22:18:46,524 - util.py[DEBUG]: loaded blob returned None, returning default.
2018-11-29 22:18:46,524 - util.py[DEBUG]: Attempting to remove /var/lib/cloud/instance
2018-11-29 22:18:46,524 - util.py[DEBUG]: Creating symbolic link from '/var/lib/cloud/instance' => '/var/lib/cloud/instances/i-059b6deeca7efcb25'
2018-11-29 22:18:46,525 - util.py[DEBUG]: Reading from /var/lib/cloud/instances/i-059b6deeca7efcb25/datasource (quiet=False)
2018-11-29 22:18:46,525 - util.py[DEBUG]: Writing to /var/lib/cloud/instances/i-059b6deeca7efcb25/datasource - wb: [644] 39 bytes
2018-11-29 22:18:46,526 - util.py[DEBUG]: Writing to /var/lib/cloud/data/previous-datasource - wb: [644] 39 bytes
2018-11-29 22:18:46,526 - util.py[DEBUG]: Reading from /var/lib/cloud/data/instance-id (quiet=False)
2018-11-29 22:18:46,526 - stages.py[DEBUG]: previous iid found to be NO_PREVIOUS_INSTANCE_ID
2018-11-29 22:18:46,526 - util.py[DEBUG]: Writing to /var/lib/cloud/data/instance-id - wb: [644] 20 bytes
2018-11-29 22:18:46,527 - util.py[DEBUG]: Writing to /run/cloud-init/.instance-id - wb: [644] 20 bytes
2018-11-29 22:18:46,527 - util.py[DEBUG]: Writing to /var/lib/cloud/data/previous-instance-id - wb: [644] 24 bytes
2018-11-29 22:18:46,528 - util.py[DEBUG]: Writing to /var/lib/cloud/instance/obj.pkl - wb: [400] 9821 bytes
2018-11-29 22:18:46,528 - main.py[DEBUG]: [local] init will now be targeting instance id: i-059b6deeca7efcb25. new=True
2018-11-29 22:18:46,528 - util.py[DEBUG]: Reading from /etc/cloud/cloud.cfg (quiet=False)
2018-11-29 22:18:46,528 - util.py[DEBUG]: Read 3169 bytes from /etc/cloud/cloud.cfg
2018-11-29 22:18:46,528 - util.py[DEBUG]: Attempting to load yaml from string of length 3169 with allowed root types (<class 'dict'>,)
2018-11-29 22:18:46,539 - util.py[DEBUG]: Reading from /etc/cloud/cloud.cfg.d/90_dpkg.cfg (quiet=False)
2018-11-29 22:18:46,539 - util.py[DEBUG]: Read 238 bytes from /etc/cloud/cloud.cfg.d/90_dpkg.cfg
2018-11-29 22:18:46,539 - util.py[DEBUG]: Attempting to load yaml from string of length 238 with allowed root types (<class 'dict'>,)
2018-11-29 22:18:46,540 - util.py[DEBUG]: Reading from /etc/cloud/cloud.cfg.d/05_logging.cfg (quiet=False)
2018-11-29 22:18:46,540 - util.py[DEBUG]: Read 2057 bytes from /etc/cloud/cloud.cfg.d/05_logging.cfg
2018-11-29 22:18:46,540 - util.py[DEBUG]: Attempting to load yaml from string of length 2057 with allowed root types (<class 'dict'>,)
2018-11-29 22:18:46,544 - util.py[DEBUG]: Reading from /run/cloud-init/cloud.cfg (quiet=False)
2018-11-29 22:18:46,544 - util.py[DEBUG]: Read 44 bytes from /run/cloud-init/cloud.cfg
2018-11-29 22:18:46,544 - util.py[DEBUG]: Attempting to load yaml from string of length 44 with allowed root types (<class 'dict'>,)
2018-11-29 22:18:46,544 - util.py[DEBUG]: Attempting to load yaml from string of length 0 with allowed root types (<class 'dict'>,)
2018-11-29 22:18:46,544 - util.py[DEBUG]: loaded blob returned None, returning default.
2018-11-29 22:18:46,545 - stages.py[DEBUG]: Using distro class <class 'cloudinit.distros.ubuntu.Distro'>
2018-11-29 22:18:46,546 - cc_set_hostname.py[DEBUG]: Setting the hostname to ip-10-0-0-188.eu-central-1.compute.internal (ip-10-0-0-188)
2018-11-29 22:18:46,546 - util.py[DEBUG]: Reading from /etc/hostname (quiet=False)
2018-11-29 22:18:46,546 - util.py[DEBUG]: Read 7 bytes from /etc/hostname
2018-11-29 22:18:46,546 - util.py[DEBUG]: Writing to /etc/hostname - wb: [644] 14 bytes
2018-11-29 22:18:46,546 - __init__.py[DEBUG]: Non-persistently setting the system hostname to ip-10-0-0-188
2018-11-29 22:18:46,547 - util.py[DEBUG]: Running command ['hostname', 'ip-10-0-0-188'] with allowed return codes [0] (shell=False, capture=True)
2018-11-29 22:18:46,549 - util.py[DEBUG]: Reading from /sys/class/net/ens3/address (quiet=False)
2018-11-29 22:18:46,549 - util.py[DEBUG]: Read 18 bytes from /sys/class/net/ens3/address
2018-11-29 22:18:46,550 - stages.py[DEBUG]: applying net config names for {'version': 1, 'config': [{'subnets': [{'type': 'dhcp4'}], 'type': 'physical', 'mac_address': '02:91:e1:a5:f7:d8', 'name': 'ens3'}]}
2018-11-29 22:18:46,550 - util.py[DEBUG]: Reading from /sys/class/net/ens3/device/device (quiet=False)
2018-11-29 22:18:46,550 - util.py[DEBUG]: Read 7 bytes from /sys/class/net/ens3/device/device
2018-11-29 22:18:46,550 - util.py[DEBUG]: Reading from /sys/class/net/lo/addr_assign_type (quiet=False)
2018-11-29 22:18:46,550 - util.py[DEBUG]: Read 2 bytes from /sys/class/net/lo/addr_assign_type
2018-11-29 22:18:46,550 - util.py[DEBUG]: Reading from /sys/class/net/lo/uevent (quiet=False)
2018-11-29 22:18:46,550 - util.py[DEBUG]: Read 23 bytes from /sys/class/net/lo/uevent
2018-11-29 22:18:46,550 - util.py[DEBUG]: Reading from /sys/class/net/lo/address (quiet=False)
2018-11-29 22:18:46,550 - util.py[DEBUG]: Read 18 bytes from /sys/class/net/lo/address
2018-11-29 22:18:46,550 - util.py[DEBUG]: Reading from /sys/class/net/lo/device/device (quiet=False)
2018-11-29 22:18:46,550 - util.py[DEBUG]: Reading from /sys/class/net/ens3/addr_assign_type (quiet=False)
2018-11-29 22:18:46,551 - util.py[DEBUG]: Read 2 bytes from /sys/class/net/ens3/addr_assign_type
2018-11-29 22:18:46,551 - util.py[DEBUG]: Reading from /sys/class/net/ens3/uevent (quiet=False)
2018-11-29 22:18:46,551 - util.py[DEBUG]: Read 25 bytes from /sys/class/net/ens3/uevent
2018-11-29 22:18:46,551 - util.py[DEBUG]: Reading from /sys/class/net/ens3/address (quiet=False)
2018-11-29 22:18:46,551 - util.py[DEBUG]: Read 18 bytes from /sys/class/net/ens3/address
2018-11-29 22:18:46,551 - util.py[DEBUG]: Reading from /sys/class/net/ens3/device/device (quiet=False)
2018-11-29 22:18:46,551 - util.py[DEBUG]: Read 7 bytes from /sys/class/net/ens3/device/device
2018-11-29 22:18:46,551 - util.py[DEBUG]: Reading from /sys/class/net/lo/operstate (quiet=False)
2018-11-29 22:18:46,551 - util.py[DEBUG]: Read 8 bytes from /sys/class/net/lo/operstate
2018-11-29 22:18:46,551 - util.py[DEBUG]: Reading from /sys/class/net/ens3/operstate (quiet=False)
2018-11-29 22:18:46,551 - util.py[DEBUG]: Read 5 bytes from /sys/class/net/ens3/operstate
2018-11-29 22:18:46,551 - util.py[DEBUG]: Running command ['ip', '-6', 'addr', 'show', 'permanent', 'scope', 'global'] with allowed return codes [0] (shell=False, capture=True)
2018-11-29 22:18:46,554 - util.py[DEBUG]: Running command ['ip', '-4', 'addr', 'show'] with allowed return codes [0] (shell=False, capture=True)
2018-11-29 22:18:46,556 - __init__.py[DEBUG]: no work necessary for renaming of [['02:91:e1:a5:f7:d8', 'ens3', 'ixgbevf', '0x10ed']]
2018-11-29 22:18:46,556 - stages.py[INFO]: Applying network configuration from ds bringup=False: {'version': 1, 'config': [{'subnets': [{'type': 'dhcp4'}], 'type': 'physical', 'mac_address': '02:91:e1:a5:f7:d8', 'name': 'ens3'}]}
2018-11-29 22:18:46,556 - __init__.py[DEBUG]: Selected renderer 'eni' from priority list: None
2018-11-29 22:18:46,559 - util.py[DEBUG]: Writing to /etc/network/interfaces.d/50-cloud-init.cfg - wb: [644] 367 bytes
2018-11-29 22:18:46,559 - util.py[DEBUG]: Writing to /etc/udev/rules.d/70-persistent-net.rules - wb: [644] 96 bytes
2018-11-29 22:18:46,559 - main.py[DEBUG]: [local] Exiting. datasource DataSourceEc2Local not in local mode.
2018-11-29 22:18:46,560 - util.py[DEBUG]: Reading from /proc/uptime (quiet=False)
2018-11-29 22:18:46,560 - util.py[DEBUG]: Read 12 bytes from /proc/uptime
2018-11-29 22:18:46,560 - util.py[DEBUG]: cloud-init mode 'init' took 0.633 seconds (0.63)
2018-11-29 22:18:46,560 - handlers.py[DEBUG]: finish: init-local: SUCCESS: searching for local datasources
2018-11-29 22:18:47,080 - util.py[DEBUG]: Cloud-init v. 18.3-9-g2e62cb8a-0ubuntu1~16.04.2 running 'init' at Thu, 29 Nov 2018 22:18:47 +0000. Up 9.53 seconds.
2018-11-29 22:18:47,080 - main.py[DEBUG]: No kernel command line url found.
2018-11-29 22:18:47,080 - main.py[DEBUG]: Closing stdin.
2018-11-29 22:18:47,082 - util.py[DEBUG]: Writing to /var/log/cloud-init.log - ab: [644] 0 bytes
2018-11-29 22:18:47,082 - util.py[DEBUG]: Changing the ownership of /var/log/cloud-init.log to 104:4
2018-11-29 22:18:47,082 - util.py[DEBUG]: Running command ['ip', 'addr', 'show'] with allowed return codes [0] (shell=False, capture=True)
2018-11-29 22:18:47,085 - util.py[DEBUG]: Running command ['ip', '-o', 'route', 'list'] with allowed return codes [0] (shell=False, capture=True)
2018-11-29 22:18:47,087 - util.py[DEBUG]: Running command ['ip', '--oneline', '-6', 'route', 'list', 'table', 'all'] with allowed return codes [0, 1] (shell=False, capture=True)
2018-11-29 22:18:47,089 - main.py[DEBUG]: Checking to see if files that we need already exist from a previous run that would allow us to stop early.
2018-11-29 22:18:47,089 - main.py[DEBUG]: Execution continuing, no previous run detected that would allow us to stop early.
2018-11-29 22:18:47,089 - handlers.py[DEBUG]: start: init-network/check-cache: attempting to read from cache [trust]
2018-11-29 22:18:47,089 - util.py[DEBUG]: Reading from /var/lib/cloud/instance/obj.pkl (quiet=False)
2018-11-29 22:18:47,089 - util.py[DEBUG]: Read 9821 bytes from /var/lib/cloud/instance/obj.pkl
2018-11-29 22:18:47,091 - util.py[DEBUG]: Reading from /run/cloud-init/.instance-id (quiet=False)
2018-11-29 22:18:47,092 - util.py[DEBUG]: Read 20 bytes from /run/cloud-init/.instance-id
2018-11-29 22:18:47,092 - stages.py[DEBUG]: restored from cache with run check: DataSourceEc2Local
2018-11-29 22:18:47,092 - handlers.py[DEBUG]: finish: init-network/check-cache: SUCCESS: restored from cache with run check: DataSourceEc2Local
2018-11-29 22:18:47,092 - util.py[DEBUG]: Reading from /etc/cloud/cloud.cfg (quiet=False)
2018-11-29 22:18:47,092 - util.py[DEBUG]: Read 3169 bytes from /etc/cloud/cloud.cfg
2018-11-29 22:18:47,092 - util.py[DEBUG]: Attempting to load yaml from string of length 3169 with allowed root types (<class 'dict'>,)
2018-11-29 22:18:47,103 - util.py[DEBUG]: Reading from /etc/cloud/cloud.cfg.d/90_dpkg.cfg (quiet=False)
2018-11-29 22:18:47,103 - util.py[DEBUG]: Read 238 bytes from /etc/cloud/cloud.cfg.d/90_dpkg.cfg
2018-11-29 22:18:47,103 - util.py[DEBUG]: Attempting to load yaml from string of length 238 with allowed root types (<class 'dict'>,)
2018-11-29 22:18:47,105 - util.py[DEBUG]: Reading from /etc/cloud/cloud.cfg.d/05_logging.cfg (quiet=False)
2018-11-29 22:18:47,105 - util.py[DEBUG]: Read 2057 bytes from /etc/cloud/cloud.cfg.d/05_logging.cfg
2018-11-29 22:18:47,105 - util.py[DEBUG]: Attempting to load yaml from string of length 2057 with allowed root types (<class 'dict'>,)
2018-11-29 22:18:47,108 - util.py[DEBUG]: Reading from /run/cloud-init/cloud.cfg (quiet=False)
2018-11-29 22:18:47,108 - util.py[DEBUG]: Read 44 bytes from /run/cloud-init/cloud.cfg
2018-11-29 22:18:47,108 - util.py[DEBUG]: Attempting to load yaml from string of length 44 with allowed root types (<class 'dict'>,)
2018-11-29 22:18:47,109 - util.py[DEBUG]: Attempting to load yaml from string of length 0 with allowed root types (<class 'dict'>,)
2018-11-29 22:18:47,109 - util.py[DEBUG]: loaded blob returned None, returning default.
2018-11-29 22:18:47,109 - util.py[DEBUG]: Attempting to remove /var/lib/cloud/instance
2018-11-29 22:18:47,110 - util.py[DEBUG]: Creating symbolic link from '/var/lib/cloud/instance' => '/var/lib/cloud/instances/i-059b6deeca7efcb25'
2018-11-29 22:18:47,110 - util.py[DEBUG]: Reading from /var/lib/cloud/instances/i-059b6deeca7efcb25/datasource (quiet=False)
2018-11-29 22:18:47,110 - util.py[DEBUG]: Read 39 bytes from /var/lib/cloud/instances/i-059b6deeca7efcb25/datasource
2018-11-29 22:18:47,110 - util.py[DEBUG]: Writing to /var/lib/cloud/instances/i-059b6deeca7efcb25/datasource - wb: [644] 39 bytes
2018-11-29 22:18:47,111 - util.py[DEBUG]: Writing to /var/lib/cloud/data/previous-datasource - wb: [644] 39 bytes
2018-11-29 22:18:47,111 - util.py[DEBUG]: Reading from /var/lib/cloud/data/instance-id (quiet=False)
2018-11-29 22:18:47,111 - util.py[DEBUG]: Read 20 bytes from /var/lib/cloud/data/instance-id
2018-11-29 22:18:47,111 - stages.py[DEBUG]: previous iid found to be i-059b6deeca7efcb25
2018-11-29 22:18:47,111 - util.py[DEBUG]: Writing to /var/lib/cloud/data/instance-id - wb: [644] 20 bytes
2018-11-29 22:18:47,111 - util.py[DEBUG]: Writing to /run/cloud-init/.instance-id - wb: [644] 20 bytes
2018-11-29 22:18:47,112 - util.py[DEBUG]: Writing to /var/lib/cloud/data/previous-instance-id - wb: [644] 20 bytes
2018-11-29 22:18:47,112 - util.py[DEBUG]: Writing to /var/lib/cloud/instance/obj.pkl - wb: [400] 9891 bytes
2018-11-29 22:18:47,113 - main.py[DEBUG]: [net] init will now be targeting instance id: i-059b6deeca7efcb25. new=False
2018-11-29 22:18:47,113 - util.py[DEBUG]: Reading from /etc/cloud/cloud.cfg (quiet=False)
2018-11-29 22:18:47,113 - util.py[DEBUG]: Read 3169 bytes from /etc/cloud/cloud.cfg
2018-11-29 22:18:47,113 - util.py[DEBUG]: Attempting to load yaml from string of length 3169 with allowed root types (<class 'dict'>,)
2018-11-29 22:18:47,123 - util.py[DEBUG]: Reading from /etc/cloud/cloud.cfg.d/90_dpkg.cfg (quiet=False)
2018-11-29 22:18:47,123 - util.py[DEBUG]: Read 238 bytes from /etc/cloud/cloud.cfg.d/90_dpkg.cfg
2018-11-29 22:18:47,123 - util.py[DEBUG]: Attempting to load yaml from string of length 238 with allowed root types (<class 'dict'>,)
2018-11-29 22:18:47,125 - util.py[DEBUG]: Reading from /etc/cloud/cloud.cfg.d/05_logging.cfg (quiet=False)
2018-11-29 22:18:47,125 - util.py[DEBUG]: Read 2057 bytes from /etc/cloud/cloud.cfg.d/05_logging.cfg
2018-11-29 22:18:47,125 - util.py[DEBUG]: Attempting to load yaml from string of length 2057 with allowed root types (<class 'dict'>,)
2018-11-29 22:18:47,128 - util.py[DEBUG]: Reading from /run/cloud-init/cloud.cfg (quiet=False)
2018-11-29 22:18:47,128 - util.py[DEBUG]: Read 44 bytes from /run/cloud-init/cloud.cfg
2018-11-29 22:18:47,129 - util.py[DEBUG]: Attempting to load yaml from string of length 44 with allowed root types (<class 'dict'>,)
2018-11-29 22:18:47,129 - util.py[DEBUG]: Attempting to load yaml from string of length 0 with allowed root types (<class 'dict'>,)
2018-11-29 22:18:47,129 - util.py[DEBUG]: loaded blob returned None, returning default.
2018-11-29 22:18:47,130 - util.py[DEBUG]: Reading from /sys/class/net/ens3/address (quiet=False)
2018-11-29 22:18:47,130 - util.py[DEBUG]: Read 18 bytes from /sys/class/net/ens3/address
2018-11-29 22:18:47,130 - stages.py[DEBUG]: applying net config names for {'config': [{'name': 'ens3', 'mac_address': '02:91:e1:a5:f7:d8', 'type': 'physical', 'subnets': [{'type': 'dhcp4'}]}], 'version': 1}
2018-11-29 22:18:47,131 - stages.py[DEBUG]: Using distro class <class 'cloudinit.distros.ubuntu.Distro'>
2018-11-29 22:18:47,131 - util.py[DEBUG]: Reading from /sys/class/net/ens3/device/device (quiet=False)
2018-11-29 22:18:47,131 - util.py[DEBUG]: Read 7 bytes from /sys/class/net/ens3/device/device
2018-11-29 22:18:47,131 - util.py[DEBUG]: Reading from /sys/class/net/lo/addr_assign_type (quiet=False)
2018-11-29 22:18:47,131 - util.py[DEBUG]: Read 2 bytes from /sys/class/net/lo/addr_assign_type
2018-11-29 22:18:47,131 - util.py[DEBUG]: Reading from /sys/class/net/lo/uevent (quiet=False)
2018-11-29 22:18:47,131 - util.py[DEBUG]: Read 23 bytes from /sys/class/net/lo/uevent
2018-11-29 22:18:47,131 - util.py[DEBUG]: Reading from /sys/class/net/lo/address (quiet=False)
2018-11-29 22:18:47,131 - util.py[DEBUG]: Read 18 bytes from /sys/class/net/lo/address
2018-11-29 22:18:47,132 - util.py[DEBUG]: Reading from /sys/class/net/lo/device/device (quiet=False)
2018-11-29 22:18:47,132 - util.py[DEBUG]: Reading from /sys/class/net/ens3/addr_assign_type (quiet=False)
2018-11-29 22:18:47,132 - util.py[DEBUG]: Read 2 bytes from /sys/class/net/ens3/addr_assign_type
2018-11-29 22:18:47,132 - util.py[DEBUG]: Reading from /sys/class/net/ens3/uevent (quiet=False)
2018-11-29 22:18:47,132 - util.py[DEBUG]: Read 25 bytes from /sys/class/net/ens3/uevent
2018-11-29 22:18:47,132 - util.py[DEBUG]: Reading from /sys/class/net/ens3/address (quiet=False)
2018-11-29 22:18:47,132 - util.py[DEBUG]: Read 18 bytes from /sys/class/net/ens3/address
2018-11-29 22:18:47,132 - util.py[DEBUG]: Reading from /sys/class/net/ens3/device/device (quiet=False)
2018-11-29 22:18:47,132 - util.py[DEBUG]: Read 7 bytes from /sys/class/net/ens3/device/device
2018-11-29 22:18:47,132 - util.py[DEBUG]: Reading from /sys/class/net/lo/operstate (quiet=False)
2018-11-29 22:18:47,132 - util.py[DEBUG]: Read 8 bytes from /sys/class/net/lo/operstate
2018-11-29 22:18:47,132 - util.py[DEBUG]: Reading from /sys/class/net/ens3/operstate (quiet=False)
2018-11-29 22:18:47,132 - util.py[DEBUG]: Read 3 bytes from /sys/class/net/ens3/operstate
2018-11-29 22:18:47,133 - util.py[DEBUG]: Running command ['ip', '-6', 'addr', 'show', 'permanent', 'scope', 'global'] with allowed return codes [0] (shell=False, capture=True)
2018-11-29 22:18:47,134 - util.py[DEBUG]: Running command ['ip', '-4', 'addr', 'show'] with allowed return codes [0] (shell=False, capture=True)
2018-11-29 22:18:47,136 - __init__.py[DEBUG]: no work necessary for renaming of [['02:91:e1:a5:f7:d8', 'ens3', 'ixgbevf', '0x10ed']]
2018-11-29 22:18:47,137 - stages.py[DEBUG]: No network config applied. Neither a new instance nor datasource network update on 'System boot' event
2018-11-29 22:18:47,137 - handlers.py[DEBUG]: start: init-network/setup-datasource: setting up datasource
2018-11-29 22:18:47,137 - handlers.py[DEBUG]: finish: init-network/setup-datasource: SUCCESS: setting up datasource
2018-11-29 22:18:47,137 - util.py[DEBUG]: Writing to /var/lib/cloud/instances/i-059b6deeca7efcb25/user-data.txt - wb: [600] 0 bytes
2018-11-29 22:18:47,139 - util.py[DEBUG]: Writing to /var/lib/cloud/instances/i-059b6deeca7efcb25/user-data.txt.i - wb: [600] 308 bytes
2018-11-29 22:18:47,140 - util.py[DEBUG]: Writing to /var/lib/cloud/instances/i-059b6deeca7efcb25/vendor-data.txt - wb: [600] 0 bytes
2018-11-29 22:18:47,141 - util.py[DEBUG]: Writing to /var/lib/cloud/instances/i-059b6deeca7efcb25/vendor-data.txt.i - wb: [600] 308 bytes
2018-11-29 22:18:47,142 - util.py[DEBUG]: Reading from /var/lib/cloud/data/set-hostname (quiet=False)
2018-11-29 22:18:47,142 - util.py[DEBUG]: Read 89 bytes from /var/lib/cloud/data/set-hostname
2018-11-29 22:18:47,142 - cc_set_hostname.py[DEBUG]: No hostname changes. Skipping set-hostname
2018-11-29 22:18:47,142 - util.py[DEBUG]: Writing to /var/lib/cloud/instances/i-059b6deeca7efcb25/sem/consume_data - wb: [644] 24 bytes
2018-11-29 22:18:47,143 - helpers.py[DEBUG]: Running consume_data using lock (<FileLock using file '/var/lib/cloud/instances/i-059b6deeca7efcb25/sem/consume_data'>)
2018-11-29 22:18:47,143 - handlers.py[DEBUG]: start: init-network/consume-user-data: reading and applying user-data
2018-11-29 22:18:47,143 - launch_index.py[DEBUG]: Discarding 0 multipart messages which do not match launch index 0
2018-11-29 22:18:47,143 - stages.py[DEBUG]: Added default handler for {'text/cloud-config', 'text/cloud-config-jsonp'} from CloudConfigPartHandler: [['text/cloud-config-jsonp', 'text/cloud-config']]
2018-11-29 22:18:47,143 - stages.py[DEBUG]: Added default handler for {'text/x-shellscript'} from ShellScriptPartHandler: [['text/x-shellscript']]
2018-11-29 22:18:47,143 - stages.py[DEBUG]: Added default handler for {'text/cloud-boothook'} from BootHookPartHandler: [['text/cloud-boothook']]
2018-11-29 22:18:47,143 - stages.py[DEBUG]: Added default handler for {'text/upstart-job'} from UpstartJobPartHandler: [['text/upstart-job']]
2018-11-29 22:18:47,144 - __init__.py[DEBUG]: Calling handler ShellScriptPartHandler: [['text/x-shellscript']] (__begin__, None, 2) with frequency once-per-instance
2018-11-29 22:18:47,144 - __init__.py[DEBUG]: Calling handler CloudConfigPartHandler: [['text/cloud-config-jsonp', 'text/cloud-config']] (__begin__, None, 3) with frequency once-per-instance
2018-11-29 22:18:47,144 - __init__.py[DEBUG]: Calling handler BootHookPartHandler: [['text/cloud-boothook']] (__begin__, None, 2) with frequency once-per-instance
2018-11-29 22:18:47,144 - __init__.py[DEBUG]: Calling handler UpstartJobPartHandler: [['text/upstart-job']] (__begin__, None, 2) with frequency once-per-instance
2018-11-29 22:18:47,144 - __init__.py[DEBUG]: {'MIME-Version': '1.0', 'Content-Disposition': 'attachment; filename="part-001"', 'Content-Type': 'text/x-not-multipart'}
2018-11-29 22:18:47,144 - __init__.py[DEBUG]: Empty payload of type text/x-not-multipart
2018-11-29 22:18:47,144 - __init__.py[DEBUG]: Calling handler ShellScriptPartHandler: [['text/x-shellscript']] (__end__, None, 2) with frequency once-per-instance
2018-11-29 22:18:47,144 - __init__.py[DEBUG]: Calling handler CloudConfigPartHandler: [['text/cloud-config-jsonp', 'text/cloud-config']] (__end__, None, 3) with frequency once-per-instance
2018-11-29 22:18:47,144 - util.py[DEBUG]: Writing to /var/lib/cloud/instances/i-059b6deeca7efcb25/cloud-config.txt - wb: [600] 0 bytes
2018-11-29 22:18:47,145 - __init__.py[DEBUG]: Calling handler BootHookPartHandler: [['text/cloud-boothook']] (__end__, None, 2) with frequency once-per-instance
2018-11-29 22:18:47,145 - __init__.py[DEBUG]: Calling handler UpstartJobPartHandler: [['text/upstart-job']] (__end__, None, 2) with frequency once-per-instance
2018-11-29 22:18:47,145 - handlers.py[DEBUG]: finish: init-network/consume-user-data: SUCCESS: reading and applying user-data
2018-11-29 22:18:47,145 - handlers.py[DEBUG]: start: init-network/consume-vendor-data: reading and applying vendor-data
2018-11-29 22:18:47,145 - stages.py[DEBUG]: no vendordata from datasource
2018-11-29 22:18:47,145 - handlers.py[DEBUG]: finish: init-network/consume-vendor-data: SUCCESS: reading and applying vendor-data
2018-11-29 22:18:47,145 - util.py[DEBUG]: Reading from /etc/cloud/cloud.cfg (quiet=False)
2018-11-29 22:18:47,145 - util.py[DEBUG]: Read 3169 bytes from /etc/cloud/cloud.cfg
2018-11-29 22:18:47,145 - util.py[DEBUG]: Attempting to load yaml from string of length 3169 with allowed root types (<class 'dict'>,)
2018-11-29 22:18:47,155 - util.py[DEBUG]: Reading from /etc/cloud/cloud.cfg.d/90_dpkg.cfg (quiet=False)
2018-11-29 22:18:47,155 - util.py[DEBUG]: Read 238 bytes from /etc/cloud/cloud.cfg.d/90_dpkg.cfg
2018-11-29 22:18:47,155 - util.py[DEBUG]: Attempting to load yaml from string of length 238 with allowed root types (<class 'dict'>,)
2018-11-29 22:18:47,157 - util.py[DEBUG]: Reading from /etc/cloud/cloud.cfg.d/05_logging.cfg (quiet=False)
2018-11-29 22:18:47,157 - util.py[DEBUG]: Read 2057 bytes from /etc/cloud/cloud.cfg.d/05_logging.cfg
2018-11-29 22:18:47,157 - util.py[DEBUG]: Attempting to load yaml from string of length 2057 with allowed root types (<class 'dict'>,)
2018-11-29 22:18:47,160 - util.py[DEBUG]: Reading from /run/cloud-init/cloud.cfg (quiet=False)
2018-11-29 22:18:47,160 - util.py[DEBUG]: Read 44 bytes from /run/cloud-init/cloud.cfg
2018-11-29 22:18:47,160 - util.py[DEBUG]: Attempting to load yaml from string of length 44 with allowed root types (<class 'dict'>,)
2018-11-29 22:18:47,161 - util.py[DEBUG]: Attempting to load yaml from string of length 0 with allowed root types (<class 'dict'>,)
2018-11-29 22:18:47,161 - util.py[DEBUG]: loaded blob returned None, returning default.
2018-11-29 22:18:47,161 - util.py[DEBUG]: Reading from /var/lib/cloud/instance/cloud-config.txt (quiet=False)
2018-11-29 22:18:47,161 - util.py[DEBUG]: Read 0 bytes from /var/lib/cloud/instance/cloud-config.txt
2018-11-29 22:18:47,161 - util.py[DEBUG]: Attempting to load yaml from string of length 0 with allowed root types (<class 'dict'>,)
2018-11-29 22:18:47,162 - util.py[DEBUG]: loaded blob returned None, returning default.
2018-11-29 22:18:47,162 - util.py[DEBUG]: Reading from /var/lib/cloud/instance/cloud-config.txt (quiet=False)
2018-11-29 22:18:47,162 - util.py[DEBUG]: Read 0 bytes from /var/lib/cloud/instance/cloud-config.txt
2018-11-29 22:18:47,162 - util.py[DEBUG]: Attempting to load yaml from string of length 0 with allowed root types (<class 'dict'>,)
2018-11-29 22:18:47,162 - util.py[DEBUG]: loaded blob returned None, returning default.
2018-11-29 22:18:47,164 - handlers.py[DEBUG]: start: init-network/activate-datasource: activating datasource
2018-11-29 22:18:47,164 - util.py[DEBUG]: Writing to /var/lib/cloud/instance/obj.pkl - wb: [400] 9201 bytes
2018-11-29 22:18:47,165 - handlers.py[DEBUG]: finish: init-network/activate-datasource: SUCCESS: activating datasource
2018-11-29 22:18:47,165 - main.py[DEBUG]: used datasource 'DataSourceEc2Local' from 'Ec2' was in di_report's list: ['Ec2', 'None']
2018-11-29 22:18:47,252 - stages.py[DEBUG]: Using distro class <class 'cloudinit.distros.ubuntu.Distro'>
2018-11-29 22:18:47,252 - stages.py[DEBUG]: Running module migrator (<module 'cloudinit.config.cc_migrator' from '/usr/lib/python3/dist-packages/cloudinit/config/cc_migrator.py'>) with frequency always
2018-11-29 22:18:47,253 - handlers.py[DEBUG]: start: init-network/config-migrator: running config-migrator with frequency always
2018-11-29 22:18:47,253 - helpers.py[DEBUG]: Running config-migrator using lock (<cloudinit.helpers.DummyLock object at 0x7fde884a6f98>)
2018-11-29 22:18:47,253 - cc_migrator.py[DEBUG]: Migrated 0 semaphore files to there canonicalized names
2018-11-29 22:18:47,253 - handlers.py[DEBUG]: finish: init-network/config-migrator: SUCCESS: config-migrator ran successfully
2018-11-29 22:18:47,253 - stages.py[DEBUG]: Running module seed_random (<module 'cloudinit.config.cc_seed_random' from '/usr/lib/python3/dist-packages/cloudinit/config/cc_seed_random.py'>) with frequency once-per-instance
2018-11-29 22:18:47,253 - handlers.py[DEBUG]: start: init-network/config-seed_random: running config-seed_random with frequency once-per-instance
2018-11-29 22:18:47,253 - util.py[DEBUG]: Writing to /var/lib/cloud/instances/i-059b6deeca7efcb25/sem/config_seed_random - wb: [644] 23 bytes
2018-11-29 22:18:47,254 - helpers.py[DEBUG]: Running config-seed_random using lock (<FileLock using file '/var/lib/cloud/instances/i-059b6deeca7efcb25/sem/config_seed_random'>)
2018-11-29 22:18:47,254 - cc_seed_random.py[DEBUG]: no command provided
2018-11-29 22:18:47,254 - handlers.py[DEBUG]: finish: init-network/config-seed_random: SUCCESS: config-seed_random ran successfully
2018-11-29 22:18:47,254 - stages.py[DEBUG]: Running module bootcmd (<module 'cloudinit.config.cc_bootcmd' from '/usr/lib/python3/dist-packages/cloudinit/config/cc_bootcmd.py'>) with frequency always
2018-11-29 22:18:47,254 - handlers.py[DEBUG]: start: init-network/config-bootcmd: running config-bootcmd with frequency always
2018-11-29 22:18:47,254 - helpers.py[DEBUG]: Running config-bootcmd using lock (<cloudinit.helpers.DummyLock object at 0x7fde884a4048>)
2018-11-29 22:18:47,254 - cc_bootcmd.py[DEBUG]: Skipping module named bootcmd, no 'bootcmd' key in configuration
2018-11-29 22:18:47,255 - handlers.py[DEBUG]: finish: init-network/config-bootcmd: SUCCESS: config-bootcmd ran successfully
2018-11-29 22:18:47,255 - stages.py[DEBUG]: Running module write-files (<module 'cloudinit.config.cc_write_files' from '/usr/lib/python3/dist-packages/cloudinit/config/cc_write_files.py'>) with frequency once-per-instance
2018-11-29 22:18:47,255 - handlers.py[DEBUG]: start: init-network/config-write-files: running config-write-files with frequency once-per-instance
2018-11-29 22:18:47,255 - util.py[DEBUG]: Writing to /var/lib/cloud/instances/i-059b6deeca7efcb25/sem/config_write_files - wb: [644] 25 bytes
2018-11-29 22:18:47,255 - helpers.py[DEBUG]: Running config-write-files using lock (<FileLock using file '/var/lib/cloud/instances/i-059b6deeca7efcb25/sem/config_write_files'>)
2018-11-29 22:18:47,255 - cc_write_files.py[DEBUG]: Skipping module named write-files, no/empty 'write_files' key in configuration
2018-11-29 22:18:47,255 - handlers.py[DEBUG]: finish: init-network/config-write-files: SUCCESS: config-write-files ran successfully
2018-11-29 22:18:47,255 - stages.py[DEBUG]: Running module growpart (<module 'cloudinit.config.cc_growpart' from '/usr/lib/python3/dist-packages/cloudinit/config/cc_growpart.py'>) with frequency always
2018-11-29 22:18:47,256 - handlers.py[DEBUG]: start: init-network/config-growpart: running config-growpart with frequency always
2018-11-29 22:18:47,256 - helpers.py[DEBUG]: Running config-growpart using lock (<cloudinit.helpers.DummyLock object at 0x7fde884a4358>)
2018-11-29 22:18:47,256 - cc_growpart.py[DEBUG]: No 'growpart' entry in cfg.  Using default: {'ignore_growroot_disabled': False, 'mode': 'auto', 'devices': ['/']}
2018-11-29 22:18:47,256 - util.py[DEBUG]: Running command ['growpart', '--help'] with allowed return codes [0] (shell=False, capture=True)
2018-11-29 22:18:47,272 - util.py[DEBUG]: Reading from /proc/1303/mountinfo (quiet=False)
2018-11-29 22:18:47,272 - util.py[DEBUG]: Read 2627 bytes from /proc/1303/mountinfo
2018-11-29 22:18:47,272 - util.py[DEBUG]: Running command ['systemd-detect-virt', '--quiet', '--container'] with allowed return codes [0] (shell=False, capture=True)
2018-11-29 22:18:47,274 - util.py[DEBUG]: Running command ['running-in-container'] with allowed return codes [0] (shell=False, capture=True)
2018-11-29 22:18:47,276 - util.py[DEBUG]: Running command ['lxc-is-container'] with allowed return codes [0] (shell=False, capture=True)
2018-11-29 22:18:47,278 - util.py[DEBUG]: Reading from /proc/1/environ (quiet=False)
2018-11-29 22:18:47,278 - util.py[DEBUG]: Read 150 bytes from /proc/1/environ
2018-11-29 22:18:47,278 - util.py[DEBUG]: Reading from /proc/self/status (quiet=False)
2018-11-29 22:18:47,278 - util.py[DEBUG]: Read 971 bytes from /proc/self/status
2018-11-29 22:18:47,281 - util.py[DEBUG]: Reading from /etc/os-release (quiet=False)
2018-11-29 22:18:47,281 - util.py[DEBUG]: Read 298 bytes from /etc/os-release
2018-11-29 22:18:47,282 - util.py[DEBUG]: Reading from /sys/class/block/xvda1/partition (quiet=False)
2018-11-29 22:18:47,282 - util.py[DEBUG]: Read 2 bytes from /sys/class/block/xvda1/partition
2018-11-29 22:18:47,282 - util.py[DEBUG]: Reading from /sys/devices/vbd-768/block/xvda/dev (quiet=False)
2018-11-29 22:18:47,282 - util.py[DEBUG]: Read 6 bytes from /sys/devices/vbd-768/block/xvda/dev
2018-11-29 22:18:47,282 - util.py[DEBUG]: Running command ['growpart', '--dry-run', '/dev/xvda', '1'] with allowed return codes [0] (shell=False, capture=True)
2018-11-29 22:18:47,404 - util.py[DEBUG]: Running command ['growpart', '/dev/xvda', '1'] with allowed return codes [0] (shell=False, capture=True)
2018-11-29 22:18:47,451 - util.py[DEBUG]: resize_devices took 0.180 seconds
2018-11-29 22:18:47,452 - cc_growpart.py[INFO]: '/' resized: changed (/dev/xvda, 1) from 8588869120 to 107373116928
2018-11-29 22:18:47,452 - handlers.py[DEBUG]: finish: init-network/config-growpart: SUCCESS: config-growpart ran successfully
2018-11-29 22:18:47,452 - stages.py[DEBUG]: Running module resizefs (<module 'cloudinit.config.cc_resizefs' from '/usr/lib/python3/dist-packages/cloudinit/config/cc_resizefs.py'>) with frequency always
2018-11-29 22:18:47,452 - handlers.py[DEBUG]: start: init-network/config-resizefs: running config-resizefs with frequency always
2018-11-29 22:18:47,452 - helpers.py[DEBUG]: Running config-resizefs using lock (<cloudinit.helpers.DummyLock object at 0x7fde885422e8>)
2018-11-29 22:18:47,453 - schema.py[DEBUG]: Ignoring schema validation. python-jsonschema is not present
2018-11-29 22:18:47,453 - util.py[DEBUG]: Reading from /proc/1303/mountinfo (quiet=False)
2018-11-29 22:18:47,453 - util.py[DEBUG]: Read 2627 bytes from /proc/1303/mountinfo
2018-11-29 22:18:47,453 - cc_resizefs.py[DEBUG]: resize_info: dev=/dev/xvda1 mnt_point=/ path=/
2018-11-29 22:18:47,453 - util.py[DEBUG]: Running command ['systemd-detect-virt', '--quiet', '--container'] with allowed return codes [0] (shell=False, capture=True)
2018-11-29 22:18:47,455 - util.py[DEBUG]: Running command ['running-in-container'] with allowed return codes [0] (shell=False, capture=True)
2018-11-29 22:18:47,457 - util.py[DEBUG]: Running command ['lxc-is-container'] with allowed return codes [0] (shell=False, capture=True)
2018-11-29 22:18:47,459 - util.py[DEBUG]: Reading from /proc/1/environ (quiet=False)
2018-11-29 22:18:47,459 - util.py[DEBUG]: Read 150 bytes from /proc/1/environ
2018-11-29 22:18:47,459 - util.py[DEBUG]: Reading from /proc/self/status (quiet=False)
2018-11-29 22:18:47,459 - util.py[DEBUG]: Read 972 bytes from /proc/self/status
2018-11-29 22:18:47,459 - cc_resizefs.py[DEBUG]: Resizing / (ext4) using resize2fs /dev/xvda1
2018-11-29 22:18:47,459 - util.py[DEBUG]: Running command ('resize2fs', '/dev/xvda1') with allowed return codes [0] (shell=False, capture=True)
2018-11-29 22:18:47,550 - util.py[DEBUG]: Resizing took 0.090 seconds
2018-11-29 22:18:47,550 - cc_resizefs.py[DEBUG]: Resized root filesystem (type=ext4, val=True)
2018-11-29 22:18:47,550 - handlers.py[DEBUG]: finish: init-network/config-resizefs: SUCCESS: config-resizefs ran successfully
2018-11-29 22:18:47,550 - stages.py[DEBUG]: Running module disk_setup (<module 'cloudinit.config.cc_disk_setup' from '/usr/lib/python3/dist-packages/cloudinit/config/cc_disk_setup.py'>) with frequency once-per-instance
2018-11-29 22:18:47,551 - handlers.py[DEBUG]: start: init-network/config-disk_setup: running config-disk_setup with frequency once-per-instance
2018-11-29 22:18:47,551 - util.py[DEBUG]: Writing to /var/lib/cloud/instances/i-059b6deeca7efcb25/sem/config_disk_setup - wb: [644] 25 bytes
2018-11-29 22:18:47,551 - helpers.py[DEBUG]: Running config-disk_setup using lock (<FileLock using file '/var/lib/cloud/instances/i-059b6deeca7efcb25/sem/config_disk_setup'>)
2018-11-29 22:18:47,551 - handlers.py[DEBUG]: finish: init-network/config-disk_setup: SUCCESS: config-disk_setup ran successfully
2018-11-29 22:18:47,551 - stages.py[DEBUG]: Running module mounts (<module 'cloudinit.config.cc_mounts' from '/usr/lib/python3/dist-packages/cloudinit/config/cc_mounts.py'>) with frequency once-per-instance
2018-11-29 22:18:47,552 - handlers.py[DEBUG]: start: init-network/config-mounts: running config-mounts with frequency once-per-instance
2018-11-29 22:18:47,552 - util.py[DEBUG]: Writing to /var/lib/cloud/instances/i-059b6deeca7efcb25/sem/config_mounts - wb: [644] 25 bytes
2018-11-29 22:18:47,552 - helpers.py[DEBUG]: Running config-mounts using lock (<FileLock using file '/var/lib/cloud/instances/i-059b6deeca7efcb25/sem/config_mounts'>)
2018-11-29 22:18:47,552 - cc_mounts.py[DEBUG]: mounts configuration is []
2018-11-29 22:18:47,553 - util.py[DEBUG]: Reading from /etc/fstab (quiet=False)
2018-11-29 22:18:47,553 - util.py[DEBUG]: Read 51 bytes from /etc/fstab
2018-11-29 22:18:47,553 - cc_mounts.py[DEBUG]: Attempting to determine the real name of ephemeral0
2018-11-29 22:18:47,553 - cc_mounts.py[DEBUG]: changed default device ephemeral0 => None
2018-11-29 22:18:47,553 - cc_mounts.py[DEBUG]: Ignoring nonexistent default named mount ephemeral0
2018-11-29 22:18:47,553 - cc_mounts.py[DEBUG]: Attempting to determine the real name of swap
2018-11-29 22:18:47,553 - DataSourceEc2.py[DEBUG]: Unable to convert swap to a device
2018-11-29 22:18:47,553 - cc_mounts.py[DEBUG]: changed default device swap => None
2018-11-29 22:18:47,553 - cc_mounts.py[DEBUG]: Ignoring nonexistent default named mount swap
2018-11-29 22:18:47,553 - cc_mounts.py[DEBUG]: no need to setup swap
2018-11-29 22:18:47,553 - cc_mounts.py[DEBUG]: No modifications to fstab needed
2018-11-29 22:18:47,553 - handlers.py[DEBUG]: finish: init-network/config-mounts: SUCCESS: config-mounts ran successfully
2018-11-29 22:18:47,553 - stages.py[DEBUG]: Running module set_hostname (<module 'cloudinit.config.cc_set_hostname' from '/usr/lib/python3/dist-packages/cloudinit/config/cc_set_hostname.py'>) with frequency once-per-instance
2018-11-29 22:18:47,554 - handlers.py[DEBUG]: start: init-network/config-set_hostname: running config-set_hostname with frequency once-per-instance
2018-11-29 22:18:47,554 - util.py[DEBUG]: Writing to /var/lib/cloud/instances/i-059b6deeca7efcb25/sem/config_set_hostname - wb: [644] 25 bytes
2018-11-29 22:18:47,554 - helpers.py[DEBUG]: Running config-set_hostname using lock (<FileLock using file '/var/lib/cloud/instances/i-059b6deeca7efcb25/sem/config_set_hostname'>)
2018-11-29 22:18:47,554 - util.py[DEBUG]: Reading from /var/lib/cloud/data/set-hostname (quiet=False)
2018-11-29 22:18:47,554 - util.py[DEBUG]: Read 89 bytes from /var/lib/cloud/data/set-hostname
2018-11-29 22:18:47,554 - cc_set_hostname.py[DEBUG]: No hostname changes. Skipping set-hostname
2018-11-29 22:18:47,554 - handlers.py[DEBUG]: finish: init-network/config-set_hostname: SUCCESS: config-set_hostname ran successfully
2018-11-29 22:18:47,554 - stages.py[DEBUG]: Running module update_hostname (<module 'cloudinit.config.cc_update_hostname' from '/usr/lib/python3/dist-packages/cloudinit/config/cc_update_hostname.py'>) with frequency always
2018-11-29 22:18:47,555 - handlers.py[DEBUG]: start: init-network/config-update_hostname: running config-update_hostname with frequency always
2018-11-29 22:18:47,555 - helpers.py[DEBUG]: Running config-update_hostname using lock (<cloudinit.helpers.DummyLock object at 0x7fde884a42b0>)
2018-11-29 22:18:47,555 - cc_update_hostname.py[DEBUG]: Updating hostname to ip-10-0-0-188.eu-central-1.compute.internal (ip-10-0-0-188)
2018-11-29 22:18:47,555 - util.py[DEBUG]: Reading from /etc/hostname (quiet=False)
2018-11-29 22:18:47,555 - util.py[DEBUG]: Read 14 bytes from /etc/hostname
2018-11-29 22:18:47,555 - __init__.py[DEBUG]: Attempting to update hostname to ip-10-0-0-188 in 1 files
2018-11-29 22:18:47,555 - util.py[DEBUG]: Reading from /var/lib/cloud/data/previous-hostname (quiet=False)
2018-11-29 22:18:47,555 - util.py[DEBUG]: Writing to /var/lib/cloud/data/previous-hostname - wb: [644] 14 bytes
2018-11-29 22:18:47,556 - handlers.py[DEBUG]: finish: init-network/config-update_hostname: SUCCESS: config-update_hostname ran successfully
2018-11-29 22:18:47,556 - stages.py[DEBUG]: Running module update_etc_hosts (<module 'cloudinit.config.cc_update_etc_hosts' from '/usr/lib/python3/dist-packages/cloudinit/config/cc_update_etc_hosts.py'>) with frequency always
2018-11-29 22:18:47,556 - handlers.py[DEBUG]: start: init-network/config-update_etc_hosts: running config-update_etc_hosts with frequency always
2018-11-29 22:18:47,556 - helpers.py[DEBUG]: Running config-update_etc_hosts using lock (<cloudinit.helpers.DummyLock object at 0x7fde884a0c18>)
2018-11-29 22:18:47,556 - cc_update_etc_hosts.py[DEBUG]: Configuration option 'manage_etc_hosts' is not set, not managing /etc/hosts in module update_etc_hosts
2018-11-29 22:18:47,556 - handlers.py[DEBUG]: finish: init-network/config-update_etc_hosts: SUCCESS: config-update_etc_hosts ran successfully
2018-11-29 22:18:47,556 - stages.py[DEBUG]: Running module ca-certs (<module 'cloudinit.config.cc_ca_certs' from '/usr/lib/python3/dist-packages/cloudinit/config/cc_ca_certs.py'>) with frequency once-per-instance
2018-11-29 22:18:47,556 - handlers.py[DEBUG]: start: init-network/config-ca-certs: running config-ca-certs with frequency once-per-instance
2018-11-29 22:18:47,556 - util.py[DEBUG]: Writing to /var/lib/cloud/instances/i-059b6deeca7efcb25/sem/config_ca_certs - wb: [644] 25 bytes
2018-11-29 22:18:47,557 - helpers.py[DEBUG]: Running config-ca-certs using lock (<FileLock using file '/var/lib/cloud/instances/i-059b6deeca7efcb25/sem/config_ca_certs'>)
2018-11-29 22:18:47,557 - cc_ca_certs.py[DEBUG]: Skipping module named ca-certs, no 'ca-certs' key in configuration
2018-11-29 22:18:47,557 - handlers.py[DEBUG]: finish: init-network/config-ca-certs: SUCCESS: config-ca-certs ran successfully
2018-11-29 22:18:47,557 - stages.py[DEBUG]: Running module rsyslog (<module 'cloudinit.config.cc_rsyslog' from '/usr/lib/python3/dist-packages/cloudinit/config/cc_rsyslog.py'>) with frequency once-per-instance
2018-11-29 22:18:47,557 - handlers.py[DEBUG]: start: init-network/config-rsyslog: running config-rsyslog with frequency once-per-instance
2018-11-29 22:18:47,557 - util.py[DEBUG]: Writing to /var/lib/cloud/instances/i-059b6deeca7efcb25/sem/config_rsyslog - wb: [644] 25 bytes
2018-11-29 22:18:47,558 - helpers.py[DEBUG]: Running config-rsyslog using lock (<FileLock using file '/var/lib/cloud/instances/i-059b6deeca7efcb25/sem/config_rsyslog'>)
2018-11-29 22:18:47,558 - cc_rsyslog.py[DEBUG]: Skipping module named rsyslog, no 'rsyslog' key in configuration
2018-11-29 22:18:47,558 - handlers.py[DEBUG]: finish: init-network/config-rsyslog: SUCCESS: config-rsyslog ran successfully
2018-11-29 22:18:47,558 - stages.py[DEBUG]: Running module users-groups (<module 'cloudinit.config.cc_users_groups' from '/usr/lib/python3/dist-packages/cloudinit/config/cc_users_groups.py'>) with frequency once-per-instance
2018-11-29 22:18:47,558 - handlers.py[DEBUG]: start: init-network/config-users-groups: running config-users-groups with frequency once-per-instance
2018-11-29 22:18:47,558 - util.py[DEBUG]: Writing to /var/lib/cloud/instances/i-059b6deeca7efcb25/sem/config_users_groups - wb: [644] 24 bytes
2018-11-29 22:18:47,558 - helpers.py[DEBUG]: Running config-users-groups using lock (<FileLock using file '/var/lib/cloud/instances/i-059b6deeca7efcb25/sem/config_users_groups'>)
2018-11-29 22:18:47,559 - util.py[DEBUG]: Reading from /etc/os-release (quiet=True)
2018-11-29 22:18:47,559 - util.py[DEBUG]: Read 298 bytes from /etc/os-release
2018-11-29 22:18:47,559 - util.py[DEBUG]: Reading from /etc/system-image/channel.ini (quiet=True)
2018-11-29 22:18:47,559 - util.py[DEBUG]: Read 0 bytes from /etc/system-image/channel.ini
2018-11-29 22:18:47,560 - __init__.py[DEBUG]: Adding user ubuntu
2018-11-29 22:18:47,560 - util.py[DEBUG]: Running hidden command to protect sensitive input/output logstring: ['useradd', 'ubuntu', '--comment', 'Ubuntu', '--groups', 'adm,audio,cdrom,dialout,dip,floppy,lxd,netdev,plugdev,sudo,video', '--shell', '/bin/bash', '-m']
2018-11-29 22:18:47,679 - util.py[DEBUG]: Running command ['passwd', '-l', 'ubuntu'] with allowed return codes [0] (shell=False, capture=True)
2018-11-29 22:18:47,701 - util.py[DEBUG]: Reading from /etc/sudoers (quiet=False)
2018-11-29 22:18:47,701 - util.py[DEBUG]: Read 755 bytes from /etc/sudoers
2018-11-29 22:18:47,702 - util.py[DEBUG]: Writing to /etc/sudoers.d/90-cloud-init-users - wb: [440] 151 bytes
2018-11-29 22:18:47,702 - handlers.py[DEBUG]: finish: init-network/config-users-groups: SUCCESS: config-users-groups ran successfully
2018-11-29 22:18:47,703 - stages.py[DEBUG]: Running module ssh (<module 'cloudinit.config.cc_ssh' from '/usr/lib/python3/dist-packages/cloudinit/config/cc_ssh.py'>) with frequency once-per-instance
2018-11-29 22:18:47,703 - handlers.py[DEBUG]: start: init-network/config-ssh: running config-ssh with frequency once-per-instance
2018-11-29 22:18:47,703 - util.py[DEBUG]: Writing to /var/lib/cloud/instances/i-059b6deeca7efcb25/sem/config_ssh - wb: [644] 25 bytes
2018-11-29 22:18:47,703 - helpers.py[DEBUG]: Running config-ssh using lock (<FileLock using file '/var/lib/cloud/instances/i-059b6deeca7efcb25/sem/config_ssh'>)
2018-11-29 22:18:47,704 - util.py[DEBUG]: Running command ['ssh-keygen', '-t', 'rsa', '-N', '', '-f', '/etc/ssh/ssh_host_rsa_key'] with allowed return codes [0] (shell=False, capture=True)
2018-11-29 22:18:47,837 - util.py[DEBUG]: Running command ['ssh-keygen', '-t', 'dsa', '-N', '', '-f', '/etc/ssh/ssh_host_dsa_key'] with allowed return codes [0] (shell=False, capture=True)
2018-11-29 22:18:47,896 - util.py[DEBUG]: Running command ['ssh-keygen', '-t', 'ecdsa', '-N', '', '-f', '/etc/ssh/ssh_host_ecdsa_key'] with allowed return codes [0] (shell=False, capture=True)
2018-11-29 22:18:47,899 - util.py[DEBUG]: Running command ['ssh-keygen', '-t', 'ed25519', '-N', '', '-f', '/etc/ssh/ssh_host_ed25519_key'] with allowed return codes [0] (shell=False, capture=True)
2018-11-29 22:18:47,904 - util.py[DEBUG]: Changing the ownership of /home/ubuntu/.ssh to 1000:1000
2018-11-29 22:18:47,905 - util.py[DEBUG]: Reading from /etc/ssh/sshd_config (quiet=False)
2018-11-29 22:18:47,911 - util.py[DEBUG]: Read 2540 bytes from /etc/ssh/sshd_config
2018-11-29 22:18:47,912 - util.py[DEBUG]: Writing to /home/ubuntu/.ssh/authorized_keys - wb: [600] 448 bytes
2018-11-29 22:18:47,912 - util.py[DEBUG]: Changing the ownership of /home/ubuntu/.ssh/authorized_keys to 1000:1000
2018-11-29 22:18:47,913 - util.py[DEBUG]: Changing the ownership of /root/.ssh to 0:0
2018-11-29 22:18:47,913 - util.py[DEBUG]: Reading from /etc/ssh/sshd_config (quiet=False)
2018-11-29 22:18:47,913 - util.py[DEBUG]: Read 2540 bytes from /etc/ssh/sshd_config
2018-11-29 22:18:47,914 - util.py[DEBUG]: Writing to /root/.ssh/authorized_keys - wb: [600] 603 bytes
2018-11-29 22:18:47,914 - util.py[DEBUG]: Changing the ownership of /root/.ssh/authorized_keys to 0:0
2018-11-29 22:18:47,914 - handlers.py[DEBUG]: finish: init-network/config-ssh: SUCCESS: config-ssh ran successfully
2018-11-29 22:18:47,914 - main.py[DEBUG]: Ran 15 modules with 0 failures
2018-11-29 22:18:47,915 - util.py[DEBUG]: Reading from /proc/uptime (quiet=False)
2018-11-29 22:18:47,915 - util.py[DEBUG]: Read 13 bytes from /proc/uptime
2018-11-29 22:18:47,915 - util.py[DEBUG]: cloud-init mode 'init' took 0.862 seconds (0.87)
2018-11-29 22:18:47,915 - handlers.py[DEBUG]: finish: init-network: SUCCESS: searching for network datasources
2018-11-29 22:18:58,114 - util.py[DEBUG]: Cloud-init v. 18.3-9-g2e62cb8a-0ubuntu1~16.04.2 running 'modules:config' at Thu, 29 Nov 2018 22:18:58 +0000. Up 20.54 seconds.
2018-11-29 22:18:58,155 - stages.py[DEBUG]: Using distro class <class 'cloudinit.distros.ubuntu.Distro'>
2018-11-29 22:18:58,156 - stages.py[DEBUG]: Running module emit_upstart (<module 'cloudinit.config.cc_emit_upstart' from '/usr/lib/python3/dist-packages/cloudinit/config/cc_emit_upstart.py'>) with frequency always
2018-11-29 22:18:58,156 - handlers.py[DEBUG]: start: modules-config/config-emit_upstart: running config-emit_upstart with frequency always
2018-11-29 22:18:58,156 - helpers.py[DEBUG]: Running config-emit_upstart using lock (<cloudinit.helpers.DummyLock object at 0x7f98e677ef98>)
2018-11-29 22:18:58,156 - cc_emit_upstart.py[DEBUG]: no /sbin/initctl located
2018-11-29 22:18:58,156 - cc_emit_upstart.py[DEBUG]: not upstart system, 'emit_upstart' disabled
2018-11-29 22:18:58,156 - handlers.py[DEBUG]: finish: modules-config/config-emit_upstart: SUCCESS: config-emit_upstart ran successfully
2018-11-29 22:18:58,156 - stages.py[DEBUG]: Running module snap (<module 'cloudinit.config.cc_snap' from '/usr/lib/python3/dist-packages/cloudinit/config/cc_snap.py'>) with frequency once-per-instance
2018-11-29 22:18:58,157 - handlers.py[DEBUG]: start: modules-config/config-snap: running config-snap with frequency once-per-instance
2018-11-29 22:18:58,157 - util.py[DEBUG]: Writing to /var/lib/cloud/instances/i-059b6deeca7efcb25/sem/config_snap - wb: [644] 25 bytes
2018-11-29 22:18:58,157 - helpers.py[DEBUG]: Running config-snap using lock (<FileLock using file '/var/lib/cloud/instances/i-059b6deeca7efcb25/sem/config_snap'>)
2018-11-29 22:18:58,157 - cc_snap.py[DEBUG]: Skipping module named snap, no 'snap' key in configuration
2018-11-29 22:18:58,157 - handlers.py[DEBUG]: finish: modules-config/config-snap: SUCCESS: config-snap ran successfully
2018-11-29 22:18:58,157 - stages.py[DEBUG]: Running module snap_config (<module 'cloudinit.config.cc_snap_config' from '/usr/lib/python3/dist-packages/cloudinit/config/cc_snap_config.py'>) with frequency once-per-instance
2018-11-29 22:18:58,158 - handlers.py[DEBUG]: start: modules-config/config-snap_config: running config-snap_config with frequency once-per-instance
2018-11-29 22:18:58,158 - util.py[DEBUG]: Writing to /var/lib/cloud/instances/i-059b6deeca7efcb25/sem/config_snap_config - wb: [644] 25 bytes
2018-11-29 22:18:58,158 - helpers.py[DEBUG]: Running config-snap_config using lock (<FileLock using file '/var/lib/cloud/instances/i-059b6deeca7efcb25/sem/config_snap_config'>)
2018-11-29 22:18:58,158 - cc_snap_config.py[DEBUG]: No snappy config provided, skipping
2018-11-29 22:18:58,158 - handlers.py[DEBUG]: finish: modules-config/config-snap_config: SUCCESS: config-snap_config ran successfully
2018-11-29 22:18:58,158 - stages.py[DEBUG]: Running module ssh-import-id (<module 'cloudinit.config.cc_ssh_import_id' from '/usr/lib/python3/dist-packages/cloudinit/config/cc_ssh_import_id.py'>) with frequency once-per-instance
2018-11-29 22:18:58,158 - handlers.py[DEBUG]: start: modules-config/config-ssh-import-id: running config-ssh-import-id with frequency once-per-instance
2018-11-29 22:18:58,158 - util.py[DEBUG]: Writing to /var/lib/cloud/instances/i-059b6deeca7efcb25/sem/config_ssh_import_id - wb: [644] 24 bytes
2018-11-29 22:18:58,159 - helpers.py[DEBUG]: Running config-ssh-import-id using lock (<FileLock using file '/var/lib/cloud/instances/i-059b6deeca7efcb25/sem/config_ssh_import_id'>)
2018-11-29 22:18:58,159 - handlers.py[DEBUG]: finish: modules-config/config-ssh-import-id: SUCCESS: config-ssh-import-id ran successfully
2018-11-29 22:18:58,159 - stages.py[DEBUG]: Running module locale (<module 'cloudinit.config.cc_locale' from '/usr/lib/python3/dist-packages/cloudinit/config/cc_locale.py'>) with frequency once-per-instance
2018-11-29 22:18:58,159 - handlers.py[DEBUG]: start: modules-config/config-locale: running config-locale with frequency once-per-instance
2018-11-29 22:18:58,159 - util.py[DEBUG]: Writing to /var/lib/cloud/instances/i-059b6deeca7efcb25/sem/config_locale - wb: [644] 25 bytes
2018-11-29 22:18:58,160 - helpers.py[DEBUG]: Running config-locale using lock (<FileLock using file '/var/lib/cloud/instances/i-059b6deeca7efcb25/sem/config_locale'>)
2018-11-29 22:18:58,160 - util.py[DEBUG]: Reading from /etc/default/locale (quiet=False)
2018-11-29 22:18:58,160 - util.py[DEBUG]: Read 35 bytes from /etc/default/locale
2018-11-29 22:18:58,160 - cc_locale.py[DEBUG]: Setting locale to en_US.UTF-8
2018-11-29 22:18:58,160 - util.py[DEBUG]: Reading from /etc/default/locale (quiet=False)
2018-11-29 22:18:58,160 - util.py[DEBUG]: Read 35 bytes from /etc/default/locale
2018-11-29 22:18:58,160 - debian.py[DEBUG]: Generating locales for en_US.UTF-8
2018-11-29 22:18:58,160 - util.py[DEBUG]: Running command ['locale-gen', 'en_US.UTF-8'] with allowed return codes [0] (shell=False, capture=False)
2018-11-29 22:18:58,874 - debian.py[DEBUG]: Updating /etc/default/locale with locale setting LANG=en_US.UTF-8
2018-11-29 22:18:58,874 - util.py[DEBUG]: Running command ['update-locale', '--locale-file=/etc/default/locale', 'LANG=en_US.UTF-8'] with allowed return codes [0] (shell=False, capture=False)
2018-11-29 22:18:59,024 - handlers.py[DEBUG]: finish: modules-config/config-locale: SUCCESS: config-locale ran successfully
2018-11-29 22:18:59,024 - stages.py[DEBUG]: Running module set-passwords (<module 'cloudinit.config.cc_set_passwords' from '/usr/lib/python3/dist-packages/cloudinit/config/cc_set_passwords.py'>) with frequency once-per-instance
2018-11-29 22:18:59,024 - handlers.py[DEBUG]: start: modules-config/config-set-passwords: running config-set-passwords with frequency once-per-instance
2018-11-29 22:18:59,024 - util.py[DEBUG]: Writing to /var/lib/cloud/instances/i-059b6deeca7efcb25/sem/config_set_passwords - wb: [644] 25 bytes
2018-11-29 22:18:59,025 - helpers.py[DEBUG]: Running config-set-passwords using lock (<FileLock using file '/var/lib/cloud/instances/i-059b6deeca7efcb25/sem/config_set_passwords'>)
2018-11-29 22:18:59,025 - cc_set_passwords.py[DEBUG]: Leaving ssh config 'PasswordAuthentication' unchanged. ssh_pwauth=None
2018-11-29 22:18:59,025 - handlers.py[DEBUG]: finish: modules-config/config-set-passwords: SUCCESS: config-set-passwords ran successfully
2018-11-29 22:18:59,025 - stages.py[DEBUG]: Running module grub-dpkg (<module 'cloudinit.config.cc_grub_dpkg' from '/usr/lib/python3/dist-packages/cloudinit/config/cc_grub_dpkg.py'>) with frequency once-per-instance
2018-11-29 22:18:59,025 - handlers.py[DEBUG]: start: modules-config/config-grub-dpkg: running config-grub-dpkg with frequency once-per-instance
2018-11-29 22:18:59,025 - util.py[DEBUG]: Writing to /var/lib/cloud/instances/i-059b6deeca7efcb25/sem/config_grub_dpkg - wb: [644] 25 bytes
2018-11-29 22:18:59,026 - helpers.py[DEBUG]: Running config-grub-dpkg using lock (<FileLock using file '/var/lib/cloud/instances/i-059b6deeca7efcb25/sem/config_grub_dpkg'>)
2018-11-29 22:18:59,026 - cc_grub_dpkg.py[DEBUG]: Setting grub debconf-set-selections with '/dev/xvda','false'
2018-11-29 22:18:59,026 - util.py[DEBUG]: Running command ['debconf-set-selections'] with allowed return codes [0] (shell=False, capture=True)
2018-11-29 22:18:59,398 - handlers.py[DEBUG]: finish: modules-config/config-grub-dpkg: SUCCESS: config-grub-dpkg ran successfully
2018-11-29 22:18:59,398 - stages.py[DEBUG]: Running module apt-pipelining (<module 'cloudinit.config.cc_apt_pipelining' from '/usr/lib/python3/dist-packages/cloudinit/config/cc_apt_pipelining.py'>) with frequency once-per-instance
2018-11-29 22:18:59,398 - handlers.py[DEBUG]: start: modules-config/config-apt-pipelining: running config-apt-pipelining with frequency once-per-instance
2018-11-29 22:18:59,398 - util.py[DEBUG]: Writing to /var/lib/cloud/instances/i-059b6deeca7efcb25/sem/config_apt_pipelining - wb: [644] 24 bytes
2018-11-29 22:18:59,399 - helpers.py[DEBUG]: Running config-apt-pipelining using lock (<FileLock using file '/var/lib/cloud/instances/i-059b6deeca7efcb25/sem/config_apt_pipelining'>)
2018-11-29 22:18:59,399 - util.py[DEBUG]: Writing to /etc/apt/apt.conf.d/90cloud-init-pipelining - wb: [644] 80 bytes
2018-11-29 22:18:59,400 - cc_apt_pipelining.py[DEBUG]: Wrote /etc/apt/apt.conf.d/90cloud-init-pipelining with apt pipeline depth setting 0
2018-11-29 22:18:59,400 - handlers.py[DEBUG]: finish: modules-config/config-apt-pipelining: SUCCESS: config-apt-pipelining ran successfully
2018-11-29 22:18:59,400 - stages.py[DEBUG]: Running module apt-configure (<module 'cloudinit.config.cc_apt_configure' from '/usr/lib/python3/dist-packages/cloudinit/config/cc_apt_configure.py'>) with frequency once-per-instance
2018-11-29 22:18:59,400 - handlers.py[DEBUG]: start: modules-config/config-apt-configure: running config-apt-configure with frequency once-per-instance
2018-11-29 22:18:59,401 - util.py[DEBUG]: Writing to /var/lib/cloud/instances/i-059b6deeca7efcb25/sem/config_apt_configure - wb: [644] 25 bytes
2018-11-29 22:18:59,401 - helpers.py[DEBUG]: Running config-apt-configure using lock (<FileLock using file '/var/lib/cloud/instances/i-059b6deeca7efcb25/sem/config_apt_configure'>)
2018-11-29 22:18:59,401 - cc_apt_configure.py[DEBUG]: debconf_selections was not set in config
2018-11-29 22:18:59,401 - util.py[DEBUG]: Reading from /etc/os-release (quiet=True)
2018-11-29 22:18:59,401 - util.py[DEBUG]: Read 298 bytes from /etc/os-release
2018-11-29 22:18:59,402 - util.py[DEBUG]: Reading from /etc/system-image/channel.ini (quiet=True)
2018-11-29 22:18:59,402 - util.py[DEBUG]: Read 0 bytes from /etc/system-image/channel.ini
2018-11-29 22:18:59,402 - cc_apt_configure.py[DEBUG]: handling apt config: {}
2018-11-29 22:18:59,402 - util.py[DEBUG]: Running command ['lsb_release', '--all'] with allowed return codes [0] (shell=False, capture=True)
2018-11-29 22:18:59,472 - util.py[DEBUG]: Running command ['dpkg', '--print-architecture'] with allowed return codes [0] (shell=False, capture=True)
2018-11-29 22:18:59,475 - cc_apt_configure.py[DEBUG]: got primary mirror: None
2018-11-29 22:18:59,475 - cc_apt_configure.py[DEBUG]: got security mirror: None
2018-11-29 22:18:59,475 - util.py[DEBUG]: Running command ['dpkg', '--print-architecture'] with allowed return codes [0] (shell=False, capture=True)
2018-11-29 22:18:59,514 - util.py[DEBUG]: Resolving URL: http://eu-central-1.ec2.archive.ubuntu.com/ubuntu/ took 0.036 seconds
2018-11-29 22:18:59,514 - __init__.py[DEBUG]: filtered distro mirror info: {'security': 'http://security.ubuntu.com/ubuntu', 'primary': 'http://eu-central-1.ec2.archive.ubuntu.com/ubuntu/'}
2018-11-29 22:18:59,514 - cc_apt_configure.py[DEBUG]: Apt Mirror info: {'security': 'http://security.ubuntu.com/ubuntu', 'primary': 'http://eu-central-1.ec2.archive.ubuntu.com/ubuntu/', 'MIRROR': 'http://eu-central-1.ec2.archive.ubuntu.com/ubuntu/', 'PRIMARY': 'http://eu-central-1.ec2.archive.ubuntu.com/ubuntu/', 'SECURITY': 'http://security.ubuntu.com/ubuntu'}
2018-11-29 22:18:59,514 - cc_apt_configure.py[INFO]: No custom template provided, fall back to builtin
2018-11-29 22:18:59,515 - util.py[DEBUG]: Reading from /etc/cloud/templates/sources.list.ubuntu.tmpl (quiet=False)
2018-11-29 22:18:59,515 - util.py[DEBUG]: Read 2841 bytes from /etc/cloud/templates/sources.list.ubuntu.tmpl
2018-11-29 22:18:59,521 - util.py[DEBUG]: Writing to /etc/apt/sources.list - wb: [644] 3377 bytes
2018-11-29 22:18:59,522 - util.py[DEBUG]: Running command ['dpkg', '--print-architecture'] with allowed return codes [0] (shell=False, capture=True)
2018-11-29 22:18:59,525 - cc_apt_configure.py[DEBUG]: Renaming apt list /var/lib/apt/lists/archive.ubuntu.com_ubuntu_dists_xenial-updates_main_i18n_Translation-en to /var/lib/apt/lists/eu-central-1.ec2.archive.ubuntu.com_ubuntu_dists_xenial-updates_main_i18n_Translation-en
2018-11-29 22:18:59,525 - cc_apt_configure.py[DEBUG]: Renaming apt list /var/lib/apt/lists/archive.ubuntu.com_ubuntu_dists_xenial-updates_main_binary-amd64_Packages to /var/lib/apt/lists/eu-central-1.ec2.archive.ubuntu.com_ubuntu_dists_xenial-updates_main_binary-amd64_Packages
2018-11-29 22:18:59,525 - cc_apt_configure.py[DEBUG]: Renaming apt list /var/lib/apt/lists/archive.ubuntu.com_ubuntu_dists_xenial-updates_restricted_binary-amd64_Packages to /var/lib/apt/lists/eu-central-1.ec2.archive.ubuntu.com_ubuntu_dists_xenial-updates_restricted_binary-amd64_Packages
2018-11-29 22:18:59,525 - cc_apt_configure.py[DEBUG]: Renaming apt list /var/lib/apt/lists/archive.ubuntu.com_ubuntu_dists_xenial_main_i18n_Translation-en to /var/lib/apt/lists/eu-central-1.ec2.archive.ubuntu.com_ubuntu_dists_xenial_main_i18n_Translation-en
2018-11-29 22:18:59,525 - cc_apt_configure.py[DEBUG]: Renaming apt list /var/lib/apt/lists/archive.ubuntu.com_ubuntu_dists_xenial-updates_restricted_i18n_Translation-en to /var/lib/apt/lists/eu-central-1.ec2.archive.ubuntu.com_ubuntu_dists_xenial-updates_restricted_i18n_Translation-en
2018-11-29 22:18:59,526 - cc_apt_configure.py[DEBUG]: Renaming apt list /var/lib/apt/lists/archive.ubuntu.com_ubuntu_dists_xenial-updates_InRelease to /var/lib/apt/lists/eu-central-1.ec2.archive.ubuntu.com_ubuntu_dists_xenial-updates_InRelease
2018-11-29 22:18:59,526 - cc_apt_configure.py[DEBUG]: Renaming apt list /var/lib/apt/lists/archive.ubuntu.com_ubuntu_dists_xenial_InRelease to /var/lib/apt/lists/eu-central-1.ec2.archive.ubuntu.com_ubuntu_dists_xenial_InRelease
2018-11-29 22:18:59,526 - cc_apt_configure.py[DEBUG]: Renaming apt list /var/lib/apt/lists/archive.ubuntu.com_ubuntu_dists_xenial_restricted_i18n_Translation-en to /var/lib/apt/lists/eu-central-1.ec2.archive.ubuntu.com_ubuntu_dists_xenial_restricted_i18n_Translation-en
2018-11-29 22:18:59,526 - cc_apt_configure.py[DEBUG]: Renaming apt list /var/lib/apt/lists/archive.ubuntu.com_ubuntu_dists_xenial_restricted_binary-amd64_Packages to /var/lib/apt/lists/eu-central-1.ec2.archive.ubuntu.com_ubuntu_dists_xenial_restricted_binary-amd64_Packages
2018-11-29 22:18:59,526 - cc_apt_configure.py[DEBUG]: Renaming apt list /var/lib/apt/lists/archive.ubuntu.com_ubuntu_dists_xenial_main_binary-amd64_Packages to /var/lib/apt/lists/eu-central-1.ec2.archive.ubuntu.com_ubuntu_dists_xenial_main_binary-amd64_Packages
2018-11-29 22:18:59,526 - handlers.py[DEBUG]: finish: modules-config/config-apt-configure: SUCCESS: config-apt-configure ran successfully
2018-11-29 22:18:59,526 - stages.py[DEBUG]: Running module ubuntu-advantage (<module 'cloudinit.config.cc_ubuntu_advantage' from '/usr/lib/python3/dist-packages/cloudinit/config/cc_ubuntu_advantage.py'>) with frequency once-per-instance
2018-11-29 22:18:59,526 - handlers.py[DEBUG]: start: modules-config/config-ubuntu-advantage: running config-ubuntu-advantage with frequency once-per-instance
2018-11-29 22:18:59,526 - util.py[DEBUG]: Writing to /var/lib/cloud/instances/i-059b6deeca7efcb25/sem/config_ubuntu_advantage - wb: [644] 25 bytes
2018-11-29 22:18:59,527 - helpers.py[DEBUG]: Running config-ubuntu-advantage using lock (<FileLock using file '/var/lib/cloud/instances/i-059b6deeca7efcb25/sem/config_ubuntu_advantage'>)
2018-11-29 22:18:59,527 - cc_ubuntu_advantage.py[DEBUG]: Skipping module named ubuntu-advantage, no 'ubuntu-advantage' key in configuration
2018-11-29 22:18:59,527 - handlers.py[DEBUG]: finish: modules-config/config-ubuntu-advantage: SUCCESS: config-ubuntu-advantage ran successfully
2018-11-29 22:18:59,527 - stages.py[DEBUG]: Running module ntp (<module 'cloudinit.config.cc_ntp' from '/usr/lib/python3/dist-packages/cloudinit/config/cc_ntp.py'>) with frequency once-per-instance
2018-11-29 22:18:59,527 - handlers.py[DEBUG]: start: modules-config/config-ntp: running config-ntp with frequency once-per-instance
2018-11-29 22:18:59,528 - util.py[DEBUG]: Writing to /var/lib/cloud/instances/i-059b6deeca7efcb25/sem/config_ntp - wb: [644] 25 bytes
2018-11-29 22:18:59,528 - helpers.py[DEBUG]: Running config-ntp using lock (<FileLock using file '/var/lib/cloud/instances/i-059b6deeca7efcb25/sem/config_ntp'>)
2018-11-29 22:18:59,528 - cc_ntp.py[DEBUG]: Skipping module named ntp, not present or disabled by cfg
2018-11-29 22:18:59,528 - handlers.py[DEBUG]: finish: modules-config/config-ntp: SUCCESS: config-ntp ran successfully
2018-11-29 22:18:59,528 - stages.py[DEBUG]: Running module timezone (<module 'cloudinit.config.cc_timezone' from '/usr/lib/python3/dist-packages/cloudinit/config/cc_timezone.py'>) with frequency once-per-instance
2018-11-29 22:18:59,528 - handlers.py[DEBUG]: start: modules-config/config-timezone: running config-timezone with frequency once-per-instance
2018-11-29 22:18:59,528 - util.py[DEBUG]: Writing to /var/lib/cloud/instances/i-059b6deeca7efcb25/sem/config_timezone - wb: [644] 25 bytes
2018-11-29 22:18:59,529 - helpers.py[DEBUG]: Running config-timezone using lock (<FileLock using file '/var/lib/cloud/instances/i-059b6deeca7efcb25/sem/config_timezone'>)
2018-11-29 22:18:59,529 - cc_timezone.py[DEBUG]: Skipping module named timezone, no 'timezone' specified
2018-11-29 22:18:59,529 - handlers.py[DEBUG]: finish: modules-config/config-timezone: SUCCESS: config-timezone ran successfully
2018-11-29 22:18:59,529 - stages.py[DEBUG]: Running module disable-ec2-metadata (<module 'cloudinit.config.cc_disable_ec2_metadata' from '/usr/lib/python3/dist-packages/cloudinit/config/cc_disable_ec2_metadata.py'>) with frequency always
2018-11-29 22:18:59,529 - handlers.py[DEBUG]: start: modules-config/config-disable-ec2-metadata: running config-disable-ec2-metadata with frequency always
2018-11-29 22:18:59,529 - helpers.py[DEBUG]: Running config-disable-ec2-metadata using lock (<cloudinit.helpers.DummyLock object at 0x7f98e5f7dfd0>)
2018-11-29 22:18:59,529 - cc_disable_ec2_metadata.py[DEBUG]: Skipping module named disable-ec2-metadata, disabling the ec2 route not enabled
2018-11-29 22:18:59,529 - handlers.py[DEBUG]: finish: modules-config/config-disable-ec2-metadata: SUCCESS: config-disable-ec2-metadata ran successfully
2018-11-29 22:18:59,529 - stages.py[DEBUG]: Running module runcmd (<module 'cloudinit.config.cc_runcmd' from '/usr/lib/python3/dist-packages/cloudinit/config/cc_runcmd.py'>) with frequency once-per-instance
2018-11-29 22:18:59,530 - handlers.py[DEBUG]: start: modules-config/config-runcmd: running config-runcmd with frequency once-per-instance
2018-11-29 22:18:59,530 - util.py[DEBUG]: Writing to /var/lib/cloud/instances/i-059b6deeca7efcb25/sem/config_runcmd - wb: [644] 25 bytes
2018-11-29 22:18:59,530 - helpers.py[DEBUG]: Running config-runcmd using lock (<FileLock using file '/var/lib/cloud/instances/i-059b6deeca7efcb25/sem/config_runcmd'>)
2018-11-29 22:18:59,530 - cc_runcmd.py[DEBUG]: Skipping module named runcmd, no 'runcmd' key in configuration
2018-11-29 22:18:59,530 - handlers.py[DEBUG]: finish: modules-config/config-runcmd: SUCCESS: config-runcmd ran successfully
2018-11-29 22:18:59,530 - stages.py[DEBUG]: Running module byobu (<module 'cloudinit.config.cc_byobu' from '/usr/lib/python3/dist-packages/cloudinit/config/cc_byobu.py'>) with frequency once-per-instance
2018-11-29 22:18:59,530 - handlers.py[DEBUG]: start: modules-config/config-byobu: running config-byobu with frequency once-per-instance
2018-11-29 22:18:59,530 - util.py[DEBUG]: Writing to /var/lib/cloud/instances/i-059b6deeca7efcb25/sem/config_byobu - wb: [644] 24 bytes
2018-11-29 22:18:59,531 - helpers.py[DEBUG]: Running config-byobu using lock (<FileLock using file '/var/lib/cloud/instances/i-059b6deeca7efcb25/sem/config_byobu'>)
2018-11-29 22:18:59,531 - cc_byobu.py[DEBUG]: Skipping module named byobu, no 'byobu' values found
2018-11-29 22:18:59,531 - handlers.py[DEBUG]: finish: modules-config/config-byobu: SUCCESS: config-byobu ran successfully
2018-11-29 22:18:59,531 - main.py[DEBUG]: Ran 15 modules with 0 failures
2018-11-29 22:18:59,532 - util.py[DEBUG]: Reading from /proc/uptime (quiet=False)
2018-11-29 22:18:59,532 - util.py[DEBUG]: Read 13 bytes from /proc/uptime
2018-11-29 22:18:59,532 - util.py[DEBUG]: cloud-init mode 'modules' took 1.464 seconds (1.46)
2018-11-29 22:18:59,532 - handlers.py[DEBUG]: finish: modules-config: SUCCESS: running modules for config
2018-11-29 22:18:59,817 - util.py[DEBUG]: Cloud-init v. 18.3-9-g2e62cb8a-0ubuntu1~16.04.2 running 'modules:final' at Thu, 29 Nov 2018 22:18:59 +0000. Up 22.24 seconds.
2018-11-29 22:18:59,852 - stages.py[DEBUG]: Using distro class <class 'cloudinit.distros.ubuntu.Distro'>
2018-11-29 22:18:59,853 - stages.py[DEBUG]: Running module snappy (<module 'cloudinit.config.cc_snappy' from '/usr/lib/python3/dist-packages/cloudinit/config/cc_snappy.py'>) with frequency once-per-instance
2018-11-29 22:18:59,853 - handlers.py[DEBUG]: start: modules-final/config-snappy: running config-snappy with frequency once-per-instance
2018-11-29 22:18:59,853 - util.py[DEBUG]: Writing to /var/lib/cloud/instances/i-059b6deeca7efcb25/sem/config_snappy - wb: [644] 25 bytes
2018-11-29 22:18:59,854 - helpers.py[DEBUG]: Running config-snappy using lock (<FileLock using file '/var/lib/cloud/instances/i-059b6deeca7efcb25/sem/config_snappy'>)
2018-11-29 22:18:59,854 - util.py[DEBUG]: Reading from /etc/os-release (quiet=True)
2018-11-29 22:18:59,854 - util.py[DEBUG]: Read 298 bytes from /etc/os-release
2018-11-29 22:18:59,854 - util.py[DEBUG]: Reading from /etc/system-image/channel.ini (quiet=True)
2018-11-29 22:18:59,854 - util.py[DEBUG]: Read 0 bytes from /etc/system-image/channel.ini
2018-11-29 22:18:59,855 - cc_snappy.py[DEBUG]: snappy: 'auto' mode, and system not snappy
2018-11-29 22:18:59,855 - handlers.py[DEBUG]: finish: modules-final/config-snappy: SUCCESS: config-snappy ran successfully
2018-11-29 22:18:59,855 - stages.py[DEBUG]: Running module package-update-upgrade-install (<module 'cloudinit.config.cc_package_update_upgrade_install' from '/usr/lib/python3/dist-packages/cloudinit/config/cc_package_update_upgrade_install.py'>) with frequency once-per-instance
2018-11-29 22:18:59,855 - handlers.py[DEBUG]: start: modules-final/config-package-update-upgrade-install: running config-package-update-upgrade-install with frequency once-per-instance
2018-11-29 22:18:59,855 - util.py[DEBUG]: Writing to /var/lib/cloud/instances/i-059b6deeca7efcb25/sem/config_package_update_upgrade_install - wb: [644] 24 bytes
2018-11-29 22:18:59,856 - helpers.py[DEBUG]: Running config-package-update-upgrade-install using lock (<FileLock using file '/var/lib/cloud/instances/i-059b6deeca7efcb25/sem/config_package_update_upgrade_install'>)
2018-11-29 22:18:59,856 - handlers.py[DEBUG]: finish: modules-final/config-package-update-upgrade-install: SUCCESS: config-package-update-upgrade-install ran successfully
2018-11-29 22:18:59,856 - stages.py[DEBUG]: Running module fan (<module 'cloudinit.config.cc_fan' from '/usr/lib/python3/dist-packages/cloudinit/config/cc_fan.py'>) with frequency once-per-instance
2018-11-29 22:18:59,856 - handlers.py[DEBUG]: start: modules-final/config-fan: running config-fan with frequency once-per-instance
2018-11-29 22:18:59,856 - util.py[DEBUG]: Writing to /var/lib/cloud/instances/i-059b6deeca7efcb25/sem/config_fan - wb: [644] 25 bytes
2018-11-29 22:18:59,857 - helpers.py[DEBUG]: Running config-fan using lock (<FileLock using file '/var/lib/cloud/instances/i-059b6deeca7efcb25/sem/config_fan'>)
2018-11-29 22:18:59,857 - cc_fan.py[DEBUG]: fan: no 'fan' config entry. disabling
2018-11-29 22:18:59,857 - handlers.py[DEBUG]: finish: modules-final/config-fan: SUCCESS: config-fan ran successfully
2018-11-29 22:18:59,857 - stages.py[DEBUG]: Running module landscape (<module 'cloudinit.config.cc_landscape' from '/usr/lib/python3/dist-packages/cloudinit/config/cc_landscape.py'>) with frequency once-per-instance
2018-11-29 22:18:59,857 - handlers.py[DEBUG]: start: modules-final/config-landscape: running config-landscape with frequency once-per-instance
2018-11-29 22:18:59,857 - util.py[DEBUG]: Writing to /var/lib/cloud/instances/i-059b6deeca7efcb25/sem/config_landscape - wb: [644] 24 bytes
2018-11-29 22:18:59,857 - helpers.py[DEBUG]: Running config-landscape using lock (<FileLock using file '/var/lib/cloud/instances/i-059b6deeca7efcb25/sem/config_landscape'>)
2018-11-29 22:18:59,857 - handlers.py[DEBUG]: finish: modules-final/config-landscape: SUCCESS: config-landscape ran successfully
2018-11-29 22:18:59,858 - stages.py[DEBUG]: Running module lxd (<module 'cloudinit.config.cc_lxd' from '/usr/lib/python3/dist-packages/cloudinit/config/cc_lxd.py'>) with frequency once-per-instance
2018-11-29 22:18:59,858 - handlers.py[DEBUG]: start: modules-final/config-lxd: running config-lxd with frequency once-per-instance
2018-11-29 22:18:59,858 - util.py[DEBUG]: Writing to /var/lib/cloud/instances/i-059b6deeca7efcb25/sem/config_lxd - wb: [644] 25 bytes
2018-11-29 22:18:59,858 - helpers.py[DEBUG]: Running config-lxd using lock (<FileLock using file '/var/lib/cloud/instances/i-059b6deeca7efcb25/sem/config_lxd'>)
2018-11-29 22:18:59,858 - cc_lxd.py[DEBUG]: Skipping module named lxd, not present or disabled by cfg
2018-11-29 22:18:59,858 - handlers.py[DEBUG]: finish: modules-final/config-lxd: SUCCESS: config-lxd ran successfully
2018-11-29 22:18:59,858 - stages.py[DEBUG]: Running module puppet (<module 'cloudinit.config.cc_puppet' from '/usr/lib/python3/dist-packages/cloudinit/config/cc_puppet.py'>) with frequency once-per-instance
2018-11-29 22:18:59,859 - handlers.py[DEBUG]: start: modules-final/config-puppet: running config-puppet with frequency once-per-instance
2018-11-29 22:18:59,859 - util.py[DEBUG]: Writing to /var/lib/cloud/instances/i-059b6deeca7efcb25/sem/config_puppet - wb: [644] 25 bytes
2018-11-29 22:18:59,859 - helpers.py[DEBUG]: Running config-puppet using lock (<FileLock using file '/var/lib/cloud/instances/i-059b6deeca7efcb25/sem/config_puppet'>)
2018-11-29 22:18:59,859 - cc_puppet.py[DEBUG]: Skipping module named puppet, no 'puppet' configuration found
2018-11-29 22:18:59,859 - handlers.py[DEBUG]: finish: modules-final/config-puppet: SUCCESS: config-puppet ran successfully
2018-11-29 22:18:59,859 - stages.py[DEBUG]: Running module chef (<module 'cloudinit.config.cc_chef' from '/usr/lib/python3/dist-packages/cloudinit/config/cc_chef.py'>) with frequency once-per-instance
2018-11-29 22:18:59,859 - handlers.py[DEBUG]: start: modules-final/config-chef: running config-chef with frequency once-per-instance
2018-11-29 22:18:59,860 - util.py[DEBUG]: Writing to /var/lib/cloud/instances/i-059b6deeca7efcb25/sem/config_chef - wb: [644] 24 bytes
2018-11-29 22:18:59,860 - helpers.py[DEBUG]: Running config-chef using lock (<FileLock using file '/var/lib/cloud/instances/i-059b6deeca7efcb25/sem/config_chef'>)
2018-11-29 22:18:59,860 - cc_chef.py[DEBUG]: Skipping module named chef, no 'chef' key in configuration
2018-11-29 22:18:59,860 - handlers.py[DEBUG]: finish: modules-final/config-chef: SUCCESS: config-chef ran successfully
2018-11-29 22:18:59,860 - stages.py[DEBUG]: Running module mcollective (<module 'cloudinit.config.cc_mcollective' from '/usr/lib/python3/dist-packages/cloudinit/config/cc_mcollective.py'>) with frequency once-per-instance
2018-11-29 22:18:59,860 - handlers.py[DEBUG]: start: modules-final/config-mcollective: running config-mcollective with frequency once-per-instance
2018-11-29 22:18:59,860 - util.py[DEBUG]: Writing to /var/lib/cloud/instances/i-059b6deeca7efcb25/sem/config_mcollective - wb: [644] 25 bytes
2018-11-29 22:18:59,861 - helpers.py[DEBUG]: Running config-mcollective using lock (<FileLock using file '/var/lib/cloud/instances/i-059b6deeca7efcb25/sem/config_mcollective'>)
2018-11-29 22:18:59,861 - cc_mcollective.py[DEBUG]: Skipping module named mcollective, no 'mcollective' key in configuration
2018-11-29 22:18:59,861 - handlers.py[DEBUG]: finish: modules-final/config-mcollective: SUCCESS: config-mcollective ran successfully
2018-11-29 22:18:59,861 - stages.py[DEBUG]: Running module salt-minion (<module 'cloudinit.config.cc_salt_minion' from '/usr/lib/python3/dist-packages/cloudinit/config/cc_salt_minion.py'>) with frequency once-per-instance
2018-11-29 22:18:59,861 - handlers.py[DEBUG]: start: modules-final/config-salt-minion: running config-salt-minion with frequency once-per-instance
2018-11-29 22:18:59,861 - util.py[DEBUG]: Writing to /var/lib/cloud/instances/i-059b6deeca7efcb25/sem/config_salt_minion - wb: [644] 25 bytes
2018-11-29 22:18:59,862 - helpers.py[DEBUG]: Running config-salt-minion using lock (<FileLock using file '/var/lib/cloud/instances/i-059b6deeca7efcb25/sem/config_salt_minion'>)
2018-11-29 22:18:59,862 - cc_salt_minion.py[DEBUG]: Skipping module named salt-minion, no 'salt_minion' key in configuration
2018-11-29 22:18:59,862 - handlers.py[DEBUG]: finish: modules-final/config-salt-minion: SUCCESS: config-salt-minion ran successfully
2018-11-29 22:18:59,862 - stages.py[DEBUG]: Running module rightscale_userdata (<module 'cloudinit.config.cc_rightscale_userdata' from '/usr/lib/python3/dist-packages/cloudinit/config/cc_rightscale_userdata.py'>) with frequency once-per-instance
2018-11-29 22:18:59,862 - handlers.py[DEBUG]: start: modules-final/config-rightscale_userdata: running config-rightscale_userdata with frequency once-per-instance
2018-11-29 22:18:59,862 - util.py[DEBUG]: Writing to /var/lib/cloud/instances/i-059b6deeca7efcb25/sem/config_rightscale_userdata - wb: [644] 25 bytes
2018-11-29 22:18:59,862 - helpers.py[DEBUG]: Running config-rightscale_userdata using lock (<FileLock using file '/var/lib/cloud/instances/i-059b6deeca7efcb25/sem/config_rightscale_userdata'>)
2018-11-29 22:18:59,862 - cc_rightscale_userdata.py[DEBUG]: Failed to get raw userdata in module rightscale_userdata
2018-11-29 22:18:59,863 - handlers.py[DEBUG]: finish: modules-final/config-rightscale_userdata: SUCCESS: config-rightscale_userdata ran successfully
2018-11-29 22:18:59,863 - stages.py[DEBUG]: Running module scripts-vendor (<module 'cloudinit.config.cc_scripts_vendor' from '/usr/lib/python3/dist-packages/cloudinit/config/cc_scripts_vendor.py'>) with frequency once-per-instance
2018-11-29 22:18:59,863 - handlers.py[DEBUG]: start: modules-final/config-scripts-vendor: running config-scripts-vendor with frequency once-per-instance
2018-11-29 22:18:59,863 - util.py[DEBUG]: Writing to /var/lib/cloud/instances/i-059b6deeca7efcb25/sem/config_scripts_vendor - wb: [644] 25 bytes
2018-11-29 22:18:59,863 - helpers.py[DEBUG]: Running config-scripts-vendor using lock (<FileLock using file '/var/lib/cloud/instances/i-059b6deeca7efcb25/sem/config_scripts_vendor'>)
2018-11-29 22:18:59,863 - handlers.py[DEBUG]: finish: modules-final/config-scripts-vendor: SUCCESS: config-scripts-vendor ran successfully
2018-11-29 22:18:59,863 - stages.py[DEBUG]: Running module scripts-per-once (<module 'cloudinit.config.cc_scripts_per_once' from '/usr/lib/python3/dist-packages/cloudinit/config/cc_scripts_per_once.py'>) with frequency once
2018-11-29 22:18:59,864 - handlers.py[DEBUG]: start: modules-final/config-scripts-per-once: running config-scripts-per-once with frequency once
2018-11-29 22:18:59,864 - util.py[DEBUG]: Writing to /var/lib/cloud/sem/config_scripts_per_once.once - wb: [644] 25 bytes
2018-11-29 22:18:59,864 - helpers.py[DEBUG]: Running config-scripts-per-once using lock (<FileLock using file '/var/lib/cloud/sem/config_scripts_per_once.once'>)
2018-11-29 22:18:59,864 - handlers.py[DEBUG]: finish: modules-final/config-scripts-per-once: SUCCESS: config-scripts-per-once ran successfully
2018-11-29 22:18:59,864 - stages.py[DEBUG]: Running module scripts-per-boot (<module 'cloudinit.config.cc_scripts_per_boot' from '/usr/lib/python3/dist-packages/cloudinit/config/cc_scripts_per_boot.py'>) with frequency always
2018-11-29 22:18:59,864 - handlers.py[DEBUG]: start: modules-final/config-scripts-per-boot: running config-scripts-per-boot with frequency always
2018-11-29 22:18:59,865 - helpers.py[DEBUG]: Running config-scripts-per-boot using lock (<cloudinit.helpers.DummyLock object at 0x7f05ed5483c8>)
2018-11-29 22:18:59,865 - handlers.py[DEBUG]: finish: modules-final/config-scripts-per-boot: SUCCESS: config-scripts-per-boot ran successfully
2018-11-29 22:18:59,865 - stages.py[DEBUG]: Running module scripts-per-instance (<module 'cloudinit.config.cc_scripts_per_instance' from '/usr/lib/python3/dist-packages/cloudinit/config/cc_scripts_per_instance.py'>) with frequency once-per-instance
2018-11-29 22:18:59,865 - handlers.py[DEBUG]: start: modules-final/config-scripts-per-instance: running config-scripts-per-instance with frequency once-per-instance
2018-11-29 22:18:59,865 - util.py[DEBUG]: Writing to /var/lib/cloud/instances/i-059b6deeca7efcb25/sem/config_scripts_per_instance - wb: [644] 24 bytes
2018-11-29 22:18:59,865 - helpers.py[DEBUG]: Running config-scripts-per-instance using lock (<FileLock using file '/var/lib/cloud/instances/i-059b6deeca7efcb25/sem/config_scripts_per_instance'>)
2018-11-29 22:18:59,866 - handlers.py[DEBUG]: finish: modules-final/config-scripts-per-instance: SUCCESS: config-scripts-per-instance ran successfully
2018-11-29 22:18:59,866 - stages.py[DEBUG]: Running module scripts-user (<module 'cloudinit.config.cc_scripts_user' from '/usr/lib/python3/dist-packages/cloudinit/config/cc_scripts_user.py'>) with frequency once-per-instance
2018-11-29 22:18:59,866 - handlers.py[DEBUG]: start: modules-final/config-scripts-user: running config-scripts-user with frequency once-per-instance
2018-11-29 22:18:59,866 - util.py[DEBUG]: Writing to /var/lib/cloud/instances/i-059b6deeca7efcb25/sem/config_scripts_user - wb: [644] 25 bytes
2018-11-29 22:18:59,866 - helpers.py[DEBUG]: Running config-scripts-user using lock (<FileLock using file '/var/lib/cloud/instances/i-059b6deeca7efcb25/sem/config_scripts_user'>)
2018-11-29 22:18:59,866 - handlers.py[DEBUG]: finish: modules-final/config-scripts-user: SUCCESS: config-scripts-user ran successfully
2018-11-29 22:18:59,866 - stages.py[DEBUG]: Running module ssh-authkey-fingerprints (<module 'cloudinit.config.cc_ssh_authkey_fingerprints' from '/usr/lib/python3/dist-packages/cloudinit/config/cc_ssh_authkey_fingerprints.py'>) with frequency once-per-instance
2018-11-29 22:18:59,866 - handlers.py[DEBUG]: start: modules-final/config-ssh-authkey-fingerprints: running config-ssh-authkey-fingerprints with frequency once-per-instance
2018-11-29 22:18:59,867 - util.py[DEBUG]: Writing to /var/lib/cloud/instances/i-059b6deeca7efcb25/sem/config_ssh_authkey_fingerprints - wb: [644] 25 bytes
2018-11-29 22:18:59,867 - helpers.py[DEBUG]: Running config-ssh-authkey-fingerprints using lock (<FileLock using file '/var/lib/cloud/instances/i-059b6deeca7efcb25/sem/config_ssh_authkey_fingerprints'>)
2018-11-29 22:18:59,867 - util.py[DEBUG]: Reading from /etc/ssh/sshd_config (quiet=False)
2018-11-29 22:18:59,867 - util.py[DEBUG]: Read 2540 bytes from /etc/ssh/sshd_config
2018-11-29 22:18:59,868 - util.py[DEBUG]: Reading from /home/ubuntu/.ssh/authorized_keys (quiet=False)
2018-11-29 22:18:59,868 - util.py[DEBUG]: Read 448 bytes from /home/ubuntu/.ssh/authorized_keys
2018-11-29 22:18:59,905 - handlers.py[DEBUG]: finish: modules-final/config-ssh-authkey-fingerprints: SUCCESS: config-ssh-authkey-fingerprints ran successfully
2018-11-29 22:18:59,905 - stages.py[DEBUG]: Running module keys-to-console (<module 'cloudinit.config.cc_keys_to_console' from '/usr/lib/python3/dist-packages/cloudinit/config/cc_keys_to_console.py'>) with frequency once-per-instance
2018-11-29 22:18:59,905 - handlers.py[DEBUG]: start: modules-final/config-keys-to-console: running config-keys-to-console with frequency once-per-instance
2018-11-29 22:18:59,905 - util.py[DEBUG]: Writing to /var/lib/cloud/instances/i-059b6deeca7efcb25/sem/config_keys_to_console - wb: [644] 24 bytes
2018-11-29 22:18:59,906 - helpers.py[DEBUG]: Running config-keys-to-console using lock (<FileLock using file '/var/lib/cloud/instances/i-059b6deeca7efcb25/sem/config_keys_to_console'>)
2018-11-29 22:18:59,906 - util.py[DEBUG]: Running command ['/usr/lib/cloud-init/write-ssh-key-fingerprints', '', 'ssh-dss'] with allowed return codes [0] (shell=False, capture=True)
2018-11-29 22:18:59,933 - handlers.py[DEBUG]: finish: modules-final/config-keys-to-console: SUCCESS: config-keys-to-console ran successfully
2018-11-29 22:18:59,933 - stages.py[DEBUG]: Running module phone-home (<module 'cloudinit.config.cc_phone_home' from '/usr/lib/python3/dist-packages/cloudinit/config/cc_phone_home.py'>) with frequency once-per-instance
2018-11-29 22:18:59,933 - handlers.py[DEBUG]: start: modules-final/config-phone-home: running config-phone-home with frequency once-per-instance
2018-11-29 22:18:59,933 - util.py[DEBUG]: Writing to /var/lib/cloud/instances/i-059b6deeca7efcb25/sem/config_phone_home - wb: [644] 25 bytes
2018-11-29 22:18:59,934 - helpers.py[DEBUG]: Running config-phone-home using lock (<FileLock using file '/var/lib/cloud/instances/i-059b6deeca7efcb25/sem/config_phone_home'>)
2018-11-29 22:18:59,934 - cc_phone_home.py[DEBUG]: Skipping module named phone-home, no 'phone_home' configuration found
2018-11-29 22:18:59,934 - handlers.py[DEBUG]: finish: modules-final/config-phone-home: SUCCESS: config-phone-home ran successfully
2018-11-29 22:18:59,934 - stages.py[DEBUG]: Running module final-message (<module 'cloudinit.config.cc_final_message' from '/usr/lib/python3/dist-packages/cloudinit/config/cc_final_message.py'>) with frequency always
2018-11-29 22:18:59,934 - handlers.py[DEBUG]: start: modules-final/config-final-message: running config-final-message with frequency always
2018-11-29 22:18:59,934 - helpers.py[DEBUG]: Running config-final-message using lock (<cloudinit.helpers.DummyLock object at 0x7f05ecdb6cf8>)
2018-11-29 22:18:59,934 - util.py[DEBUG]: Reading from /proc/uptime (quiet=False)
2018-11-29 22:18:59,935 - util.py[DEBUG]: Read 13 bytes from /proc/uptime
2018-11-29 22:18:59,937 - util.py[DEBUG]: Cloud-init v. 18.3-9-g2e62cb8a-0ubuntu1~16.04.2 finished at Thu, 29 Nov 2018 22:18:59 +0000. Datasource DataSourceEc2Local.  Up 22.41 seconds
2018-11-29 22:18:59,937 - util.py[DEBUG]: Writing to /var/lib/cloud/instance/boot-finished - wb: [644] 79 bytes
2018-11-29 22:18:59,938 - handlers.py[DEBUG]: finish: modules-final/config-final-message: SUCCESS: config-final-message ran successfully
2018-11-29 22:18:59,938 - stages.py[DEBUG]: Running module power-state-change (<module 'cloudinit.config.cc_power_state_change' from '/usr/lib/python3/dist-packages/cloudinit/config/cc_power_state_change.py'>) with frequency once-per-instance
2018-11-29 22:18:59,938 - handlers.py[DEBUG]: start: modules-final/config-power-state-change: running config-power-state-change with frequency once-per-instance
2018-11-29 22:18:59,938 - util.py[DEBUG]: Writing to /var/lib/cloud/instances/i-059b6deeca7efcb25/sem/config_power_state_change - wb: [644] 25 bytes
2018-11-29 22:18:59,939 - helpers.py[DEBUG]: Running config-power-state-change using lock (<FileLock using file '/var/lib/cloud/instances/i-059b6deeca7efcb25/sem/config_power_state_change'>)
2018-11-29 22:18:59,939 - cc_power_state_change.py[DEBUG]: no power_state provided. doing nothing
2018-11-29 22:18:59,939 - handlers.py[DEBUG]: finish: modules-final/config-power-state-change: SUCCESS: config-power-state-change ran successfully
2018-11-29 22:18:59,939 - main.py[DEBUG]: Ran 20 modules with 0 failures
2018-11-29 22:18:59,940 - util.py[DEBUG]: Creating symbolic link from '/run/cloud-init/result.json' => '../../var/lib/cloud/data/result.json'
2018-11-29 22:18:59,940 - util.py[DEBUG]: Reading from /proc/uptime (quiet=False)
2018-11-29 22:18:59,940 - util.py[DEBUG]: Read 13 bytes from /proc/uptime
2018-11-29 22:18:59,940 - util.py[DEBUG]: cloud-init mode 'modules' took 0.170 seconds (0.17)
2018-11-29 22:18:59,940 - handlers.py[DEBUG]: finish: modules-final: SUCCESS: running modules for final
